File: lab_data_arola_UW/PPS Data/PPS_DSC/8-4-21_PPS_Unaged_20C PPS_Unaged_20C_min.csv
Filename,8-4-21_PPS_Unaged_20C PPS_Unaged_20C_min
Instrument name,DSC2A-01586 (192.168.10.2)
Operator,Carly Travis
rundate,8/4/2021
Sample name,8-4-21_PPS_Unaged_20C
proceduresegments,Initial Temperature 40.00 °C; Ramp 20.00 °C/min to 300.00 °C; Ramp 20.00 °C/min to 40.00 °C
[File Parameters]
Run date,8/4/2021 2:58:59 PM
Trios version,5.1.1.46572
Original File Name,
Current File Name,C:\ProgramData\TA Instruments\TRIOS\Data\Arola Lab\Carly Travis\8-4-21_PPS_Unaged_20C PPS_Unaged_20C_min.tri
[Procedure]
Procedure Name,PPS_Unaged_20C_min
Sample Name,8-4-21_PPS_Unaged_20C
Sample Mass,4.1 mg
Reference Sample Mass,0 mg
Pan Mass,51.8 mg
Pan Number,33
Reference Pan Mass,51.8 mg
Reference Pan Number,52
Pan Type,Tzero Aluminum
Comments,Rerun of PPS at 20 C/min to 300C
Project Name,
Operator,Carly Travis
Test,Custom
Unload Max Temperature,40
Unload Min Temperature,40
Load Max Temperature,40
Load Min Temperature,40
Stop on Gas Flow Error,Yes
[Signal List]
Signal #1,Time (min)
Signal #2,Temperature (°C)
Signal #3,Heat Flow (mW)
Signal #4,Delta T (µV)
Signal #5,Delta Tzero (µV)
Signal #6,Tzero Temperature (°C)
Signal #7,Cell Purge (mL/min)
Signal #8,Heater Temp (°C)
Signal #9,Power Delivered (W)
Signal #10,Reference Junction Temperature (°C)
Signal #11,Flange Temperature (°C)
Signal #12,Heat Flow Phase (rad)
Signal #13,Total Heat Capacity (J/°C)
Signal #14,Heat Capacity (J/°C)
[Configuration]
Company Name,UW
Instrument Name,DSC2A-01586
Instrument Type,DSC2500
Serial Number,DSC2A-01586
IP,192.168.10.2
Location of Instrument,UW Bagley 83
DisplayType,TianmaV2
Sample Interval ,0.1 s/pt
Selected Heat Flow,T4P
Exotherm Direction,Up
Cell Serial,DRC2-03254
Lid Type,High Temperature
Cooler,RCS 90
Leave Cooler on at End of Sequence,Off
Gas 2,Nitrogen
Gas Selected,Channel 1
Flow Rate,50 mL/min
Secondary Purge,Off
Licensed Heat Flow,Heat Flow T4P
Modulation Licensed,Yes
[Versions]
Common IDD Version,1
Cortex Version,VER 2.10.2.31
Driver,5.0.0.6
GDM Version,1.0.3.3
TouchscreenVersion,1.0.0.16145
FEP Version,1.2.1.21
FEP Bootloader,2.0.0.5
AutoSampler Version,2.1.1.26
Auto Sampler Bootloader,2.0.0.5
FCM Version,1.1.0.3
FCM Bootloader,2.0.0.5
[Experiment Logs]
Experiment Log Entry # 1,Air Cool is off.
Experiment Log Entry # 3,Intial Temperature Segment 40 C Started
Experiment Log Entry # 5,Ramp Segment 20 C/min to 300 Started
Experiment Log Entry # 7,Ramp Segment 20 C/min to 40 Started
[Method Log]
Method Log Entry # 1,Initial Temperature 40 °C
Method Log Entry # 2,(Ramp 217629) Ramp 20 °C/minute to 300 °C
Method Log Entry # 3,(Ramp 217630) Ramp 20 °C/minute to 40 °C
Cell Serial,DRC2-03254
[T1 Calibration]
Date Applied,11/4/2020 3:37:40 PM
Slope,-0.0005345262
Offset,-9.566325
Initial Temperature,-40.80371
GUID,dc124dba-dc9a-4fde-8ac5-9ad7a93db68c
[TZero Calibration]
Date Applied,11/4/2020 11:48:17 PM
Description,From -90.213 °C to 395.512 °C at 20.000°C/min
Gas Type,Nitrogen
Pan Type,None
Source Files 1,C:\ProgramData\TA Instruments\TRIOS\Data\TA SERVICE\DSC2A-01586\Recalibration 04NOV2020 2\Tzero Baseline 110420.tri
Source Files 2,C:\ProgramData\TA Instruments\TRIOS\Data\TA SERVICE\DSC2A-01586\Recalibration 04NOV2020 2\Tzero Sapphire 110420.tri
Delta T Offset,-9.068947
Delta T Slope,-0.0005966381
Delta T0 Offset,4.937698
Delta T0 Slope,0.01193379
[Temperature Calibration]
Date Applied,11/5/2020 1:08:46 AM
Description,From 106.590 °C to 186.590 °C at 10.000°C/min
Gas Type,Nitrogen
Pan Type,Tzero Aluminum
Source Files 1,C:\ProgramData\TA Instruments\TRIOS\Data\TA SERVICE\DSC2A-01586\Recalibration 04NOV2020 2\Indium 110420.tri
Measured 1,157.6191
Known 1,156.598
[Cell Constant Calibration]
Date Applied,11/5/2020 1:08:46 AM
Description,From 106.590 °C to 186.590 °C at 10.000°C/min
Gas Type,Nitrogen
Pan Type,Tzero Aluminum
Source Files 1,C:\ProgramData\TA Instruments\TRIOS\Data\TA SERVICE\DSC2A-01586\Recalibration 04NOV2020 2\Indium 110420.tri
T4P KCell,1.073014
Onset Slope,-60.30231 mW/°C
[Direct Cp Calibration]
(Not Applied),
[Rev Cp Calibration]
(Not Applied),
[step]
Ramp 20.00 °C/min to 300.00 °C
Time,Temperature,Heat Flow (Normalized)
min,°C,W/g
0.00,40.00,-0.010
0.01,40.00,-0.010
0.02,40.01,-0.010
0.03,40.01,-0.010
0.04,40.02,-0.011
0.05,40.04,-0.026
0.06,40.06,-0.043
0.07,40.09,-0.060
0.08,40.14,-0.076
0.09,40.20,-0.092
0.10,40.27,-0.106
0.11,40.36,-0.117
0.12,40.46,-0.129
0.13,40.57,-0.137
0.14,40.70,-0.146
0.15,40.83,-0.157
0.16,40.97,-0.167
0.17,41.11,-0.177
0.18,41.26,-0.187
0.19,41.42,-0.199
0.20,41.58,-0.209
0.21,41.74,-0.219
0.22,41.90,-0.230
0.23,42.07,-0.239
0.24,42.25,-0.248
0.25,42.42,-0.256
0.26,42.60,-0.263
0.27,42.78,-0.270
0.28,42.96,-0.275
0.29,43.15,-0.280
0.30,43.33,-0.285
0.31,43.52,-0.290
0.32,43.71,-0.298
0.33,43.90,-0.299
0.34,44.09,-0.303
0.35,44.28,-0.306
0.36,44.47,-0.309
0.37,44.67,-0.313
0.38,44.86,-0.315
0.39,45.05,-0.318
0.40,45.25,-0.320
0.41,45.44,-0.323
0.42,45.64,-0.324
0.43,45.84,-0.327
0.44,46.03,-0.328
0.45,46.23,-0.330
0.46,46.43,-0.330
0.47,46.62,-0.332
0.48,46.82,-0.333
0.49,47.02,-0.334
0.50,47.22,-0.335
0.51,47.41,-0.336
0.52,47.61,-0.337
0.53,47.81,-0.337
0.54,48.01,-0.338
0.55,48.21,-0.338
0.56,48.41,-0.338
0.57,48.60,-0.339
0.58,48.80,-0.339
0.59,49.00,-0.339
0.60,49.20,-0.338
0.61,49.40,-0.339
0.62,49.60,-0.339
0.63,49.80,-0.339
0.64,50.00,-0.341
0.65,50.20,-0.343
0.66,50.40,-0.344
0.67,50.59,-0.345
0.68,50.79,-0.345
0.69,50.99,-0.346
0.70,51.19,-0.346
0.71,51.39,-0.347
0.72,51.59,-0.347
0.73,51.79,-0.347
0.74,51.99,-0.348
0.75,52.19,-0.348
0.76,52.39,-0.348
0.77,52.59,-0.349
0.78,52.79,-0.349
0.79,52.99,-0.349
0.80,53.19,-0.349
0.81,53.39,-0.350
0.82,53.59,-0.350
0.83,53.79,-0.350
0.84,53.99,-0.350
0.85,54.19,-0.351
0.86,54.38,-0.351
0.87,54.58,-0.351
0.88,54.78,-0.352
0.89,54.98,-0.352
0.90,55.18,-0.352
0.91,55.38,-0.353
0.92,55.58,-0.353
0.93,55.78,-0.353
0.94,55.98,-0.353
0.95,56.18,-0.354
0.96,56.38,-0.354
0.97,56.58,-0.354
0.98,56.78,-0.354
0.99,56.98,-0.355
1.00,57.18,-0.355
1.01,57.38,-0.355
1.02,57.58,-0.355
1.03,57.78,-0.356
1.04,57.98,-0.356
1.05,58.18,-0.356
1.06,58.38,-0.356
1.07,58.58,-0.357
1.08,58.78,-0.357
1.09,58.98,-0.357
1.10,59.18,-0.357
1.11,59.38,-0.357
1.12,59.58,-0.358
1.13,59.78,-0.358
1.14,59.98,-0.358
1.15,60.18,-0.359
1.16,60.38,-0.359
1.17,60.58,-0.359
1.18,60.78,-0.359
1.19,60.98,-0.360
1.20,61.18,-0.360
1.21,61.38,-0.360
1.22,61.58,-0.360
1.23,61.78,-0.361
1.24,61.98,-0.361
1.25,62.18,-0.361
1.26,62.38,-0.361
1.27,62.58,-0.362
1.28,62.78,-0.362
1.29,62.98,-0.362
1.30,63.18,-0.362
1.31,63.38,-0.362
1.32,63.58,-0.363
1.33,63.78,-0.363
1.34,63.98,-0.363
1.35,64.18,-0.363
1.36,64.38,-0.364
1.37,64.58,-0.364
1.38,64.78,-0.364
1.39,64.98,-0.364
1.40,65.18,-0.364
1.41,65.38,-0.365
1.42,65.58,-0.365
1.43,65.78,-0.365
1.44,65.98,-0.365
1.45,66.18,-0.366
1.46,66.38,-0.366
1.47,66.58,-0.366
1.48,66.78,-0.366
1.49,66.98,-0.367
1.50,67.18,-0.367
1.51,67.38,-0.367
1.52,67.58,-0.367
1.53,67.78,-0.368
1.54,67.98,-0.368
1.55,68.18,-0.368
1.56,68.38,-0.368
1.57,68.58,-0.369
1.58,68.78,-0.369
1.59,68.98,-0.369
1.60,69.18,-0.369
1.61,69.38,-0.370
1.62,69.58,-0.370
1.63,69.78,-0.370
1.64,69.98,-0.370
1.65,70.18,-0.371
1.66,70.38,-0.371
1.67,70.58,-0.371
1.68,70.78,-0.371
1.69,70.98,-0.371
1.70,71.18,-0.372
1.71,71.38,-0.372
1.72,71.58,-0.372
1.73,71.78,-0.372
1.74,71.98,-0.373
1.75,72.18,-0.373
1.76,72.38,-0.373
1.77,72.58,-0.373
1.78,72.78,-0.373
1.79,72.99,-0.374
1.80,73.18,-0.374
1.81,73.38,-0.374
1.82,73.58,-0.374
1.83,73.78,-0.374
1.84,73.99,-0.375
1.85,74.19,-0.375
1.86,74.39,-0.375
1.87,74.58,-0.375
1.88,74.79,-0.375
1.89,74.99,-0.375
1.90,75.19,-0.375
1.91,75.39,-0.375
1.92,75.59,-0.376
1.93,75.79,-0.376
1.94,75.99,-0.376
1.95,76.19,-0.376
1.96,76.39,-0.376
1.97,76.59,-0.376
1.98,76.79,-0.376
1.99,76.99,-0.376
2.00,77.19,-0.376
2.01,77.39,-0.376
2.02,77.59,-0.377
2.03,77.79,-0.377
2.04,77.99,-0.377
2.05,78.19,-0.377
2.06,78.39,-0.377
2.07,78.59,-0.377
2.08,78.79,-0.377
2.09,78.99,-0.377
2.10,79.19,-0.378
2.11,79.39,-0.378
2.12,79.59,-0.378
2.13,79.79,-0.378
2.14,79.99,-0.378
2.15,80.19,-0.378
2.16,80.39,-0.379
2.17,80.59,-0.379
2.18,80.79,-0.379
2.19,80.99,-0.380
2.20,81.19,-0.381
2.21,81.39,-0.381
2.22,81.59,-0.381
2.23,81.79,-0.381
2.24,81.99,-0.381
2.25,82.19,-0.382
2.26,82.39,-0.382
2.27,82.59,-0.382
2.28,82.79,-0.382
2.29,82.99,-0.382
2.30,83.19,-0.383
2.31,83.39,-0.383
2.32,83.59,-0.383
2.33,83.79,-0.384
2.34,83.99,-0.384
2.35,84.19,-0.384
2.36,84.40,-0.385
2.37,84.60,-0.385
2.38,84.80,-0.385
2.39,85.00,-0.386
2.40,85.19,-0.387
2.41,85.40,-0.387
2.42,85.60,-0.388
2.43,85.80,-0.388
2.44,86.00,-0.389
2.45,86.20,-0.390
2.46,86.40,-0.391
2.47,86.60,-0.392
2.48,86.80,-0.393
2.49,87.00,-0.394
2.50,87.20,-0.395
2.51,87.40,-0.396
2.52,87.60,-0.397
2.53,87.80,-0.398
2.54,88.00,-0.399
2.55,88.20,-0.401
2.56,88.40,-0.402
2.57,88.60,-0.403
2.58,88.80,-0.404
2.59,89.00,-0.406
2.60,89.20,-0.409
2.61,89.40,-0.411
2.62,89.60,-0.414
2.63,89.80,-0.417
2.64,90.00,-0.418
2.65,90.20,-0.420
2.66,90.40,-0.425
2.67,90.60,-0.428
2.68,90.80,-0.430
2.69,91.00,-0.433
2.70,91.20,-0.437
2.71,91.39,-0.440
2.72,91.60,-0.443
2.73,91.80,-0.448
2.74,91.99,-0.451
2.75,92.19,-0.455
2.76,92.39,-0.461
2.77,92.59,-0.464
2.78,92.79,-0.468
2.79,92.99,-0.470
2.80,93.19,-0.475
2.81,93.39,-0.480
2.82,93.59,-0.483
2.83,93.79,-0.485
2.84,93.99,-0.489
2.85,94.19,-0.492
2.86,94.39,-0.495
2.87,94.59,-0.498
2.88,94.79,-0.501
2.89,94.99,-0.504
2.90,95.19,-0.506
2.91,95.39,-0.510
2.92,95.59,-0.513
2.93,95.78,-0.514
2.94,95.98,-0.517
2.95,96.18,-0.518
2.96,96.38,-0.519
2.97,96.58,-0.519
2.98,96.78,-0.519
2.99,96.98,-0.518
3.00,97.19,-0.517
3.01,97.38,-0.516
3.02,97.59,-0.512
3.03,97.79,-0.510
3.04,97.99,-0.505
3.05,98.19,-0.502
3.06,98.39,-0.500
3.07,98.59,-0.499
3.08,98.79,-0.497
3.09,98.99,-0.494
3.10,99.19,-0.493
3.11,99.39,-0.491
3.12,99.59,-0.490
3.13,99.79,-0.489
3.14,99.99,-0.488
3.15,100.19,-0.487
3.16,100.39,-0.486
3.17,100.59,-0.485
3.18,100.80,-0.485
3.19,101.00,-0.484
3.20,101.20,-0.484
3.21,101.40,-0.482
3.22,101.60,-0.480
3.23,101.80,-0.479
3.24,102.00,-0.477
3.25,102.20,-0.476
3.26,102.40,-0.476
3.27,102.60,-0.475
3.28,102.80,-0.474
3.29,103.00,-0.474
3.30,103.20,-0.474
3.31,103.40,-0.473
3.32,103.60,-0.473
3.33,103.80,-0.473
3.34,104.00,-0.473
3.35,104.20,-0.473
3.36,104.40,-0.473
3.37,104.60,-0.472
3.38,104.80,-0.472
3.39,105.00,-0.472
3.40,105.21,-0.472
3.41,105.40,-0.472
3.42,105.61,-0.471
3.43,105.81,-0.471
3.44,106.01,-0.471
3.45,106.21,-0.471
3.46,106.41,-0.471
3.47,106.61,-0.471
3.48,106.81,-0.470
3.49,107.01,-0.470
3.50,107.21,-0.470
3.51,107.41,-0.470
3.52,107.61,-0.470
3.53,107.81,-0.470
3.54,108.01,-0.469
3.55,108.21,-0.469
3.56,108.41,-0.469
3.57,108.61,-0.469
3.58,108.81,-0.469
3.59,109.01,-0.468
3.60,109.21,-0.468
3.61,109.41,-0.468
3.62,109.61,-0.468
3.63,109.81,-0.467
3.64,110.01,-0.467
3.65,110.21,-0.466
3.66,110.41,-0.466
3.67,110.61,-0.466
3.68,110.81,-0.465
3.69,111.01,-0.465
3.70,111.22,-0.464
3.71,111.42,-0.464
3.72,111.62,-0.464
3.73,111.82,-0.463
3.74,112.02,-0.462
3.75,112.22,-0.461
3.76,112.42,-0.461
3.77,112.62,-0.460
3.78,112.82,-0.460
3.79,113.02,-0.459
3.80,113.22,-0.458
3.81,113.42,-0.457
3.82,113.62,-0.455
3.83,113.82,-0.454
3.84,114.02,-0.452
3.85,114.22,-0.450
3.86,114.42,-0.449
3.87,114.62,-0.448
3.88,114.82,-0.447
3.89,115.02,-0.445
3.90,115.22,-0.443
3.91,115.43,-0.442
3.92,115.63,-0.440
3.93,115.83,-0.437
3.94,116.03,-0.436
3.95,116.23,-0.433
3.96,116.43,-0.431
3.97,116.63,-0.430
3.98,116.83,-0.428
3.99,117.03,-0.427
4.00,117.23,-0.425
4.01,117.43,-0.421
4.02,117.63,-0.419
4.03,117.83,-0.418
4.04,118.03,-0.417
4.05,118.23,-0.414
4.06,118.44,-0.410
4.07,118.64,-0.409
4.08,118.84,-0.407
4.09,119.04,-0.404
4.10,119.24,-0.401
4.11,119.44,-0.400
4.12,119.64,-0.397
4.13,119.84,-0.395
4.14,120.04,-0.391
4.15,120.24,-0.388
4.16,120.44,-0.384
4.17,120.64,-0.381
4.18,120.84,-0.379
4.19,121.05,-0.377
4.20,121.25,-0.373
4.21,121.45,-0.369
4.22,121.65,-0.366
4.23,121.85,-0.363
4.24,122.05,-0.360
4.25,122.25,-0.355
4.26,122.45,-0.351
4.27,122.65,-0.348
4.28,122.85,-0.345
4.29,123.06,-0.338
4.30,123.26,-0.336
4.31,123.46,-0.330
4.32,123.66,-0.324
4.33,123.86,-0.321
4.34,124.06,-0.315
4.35,124.26,-0.310
4.36,124.47,-0.306
4.37,124.67,-0.297
4.38,124.87,-0.290
4.39,125.07,-0.285
4.40,125.27,-0.274
4.41,125.47,-0.268
4.42,125.67,-0.258
4.43,125.88,-0.249
4.44,126.08,-0.237
4.45,126.28,-0.226
4.46,126.48,-0.214
4.47,126.69,-0.200
4.48,126.89,-0.185
4.49,127.09,-0.167
4.50,127.29,-0.149
4.51,127.50,-0.127
4.52,127.70,-0.105
4.53,127.91,-0.083
4.54,128.11,-0.053
4.55,128.32,-0.025
4.56,128.52,0.004
4.57,128.73,0.038
4.58,128.93,0.073
4.59,129.14,0.109
4.60,129.34,0.148
4.61,129.55,0.189
4.62,129.76,0.229
4.63,129.97,0.270
4.64,130.18,0.312
4.65,130.38,0.353
4.66,130.59,0.390
4.67,130.80,0.424
4.68,131.01,0.457
4.69,131.22,0.482
4.70,131.43,0.502
4.71,131.63,0.518
4.72,131.84,0.523
4.73,132.05,0.523
4.74,132.25,0.512
4.75,132.45,0.497
4.76,132.65,0.474
4.77,132.86,0.446
4.78,133.05,0.409
4.79,133.25,0.371
4.80,133.45,0.329
4.81,133.64,0.286
4.82,133.84,0.242
4.83,134.03,0.197
4.84,134.23,0.153
4.85,134.42,0.110
4.86,134.61,0.066
4.87,134.80,0.026
4.88,134.99,-0.014
4.89,135.19,-0.052
4.90,135.38,-0.087
4.91,135.57,-0.118
4.92,135.76,-0.149
4.93,135.95,-0.176
4.94,136.15,-0.201
4.95,136.34,-0.225
4.96,136.53,-0.244
4.97,136.73,-0.262
4.98,136.92,-0.280
4.99,137.12,-0.294
5.00,137.31,-0.307
5.01,137.51,-0.319
5.02,137.70,-0.330
5.03,137.90,-0.338
5.04,138.10,-0.349
5.05,138.29,-0.358
5.06,138.49,-0.363
5.07,138.69,-0.371
5.08,138.88,-0.374
5.09,139.08,-0.382
5.10,139.28,-0.388
5.11,139.48,-0.391
5.12,139.68,-0.396
5.13,139.88,-0.399
5.14,140.07,-0.404
5.15,140.27,-0.405
5.16,140.47,-0.406
5.17,140.67,-0.411
5.18,140.87,-0.414
5.19,141.07,-0.418
5.20,141.27,-0.419
5.21,141.47,-0.422
5.22,141.67,-0.423
5.23,141.87,-0.424
5.24,142.07,-0.426
5.25,142.27,-0.427
5.26,142.47,-0.428
5.27,142.67,-0.429
5.28,142.87,-0.430
5.29,143.07,-0.432
5.30,143.26,-0.433
5.31,143.46,-0.434
5.32,143.66,-0.435
5.33,143.86,-0.436
5.34,144.06,-0.437
5.35,144.26,-0.439
5.36,144.46,-0.439
5.37,144.66,-0.441
5.38,144.86,-0.442
5.39,145.07,-0.443
5.40,145.26,-0.444
5.41,145.47,-0.444
5.42,145.66,-0.444
5.43,145.86,-0.445
5.44,146.07,-0.446
5.45,146.27,-0.446
5.46,146.46,-0.447
5.47,146.67,-0.448
5.48,146.87,-0.448
5.49,147.07,-0.449
5.50,147.27,-0.449
5.51,147.47,-0.449
5.52,147.66,-0.450
5.53,147.87,-0.450
5.54,148.06,-0.451
5.55,148.27,-0.452
5.56,148.47,-0.453
5.57,148.66,-0.453
5.58,148.87,-0.454
5.59,149.07,-0.455
5.60,149.26,-0.455
5.61,149.47,-0.457
5.62,149.67,-0.457
5.63,149.87,-0.457
5.64,150.07,-0.458
5.65,150.27,-0.458
5.66,150.47,-0.458
5.67,150.67,-0.459
5.68,150.87,-0.460
5.69,151.07,-0.460
5.70,151.27,-0.461
5.71,151.47,-0.461
5.72,151.67,-0.462
5.73,151.87,-0.463
5.74,152.07,-0.463
5.75,152.27,-0.463
5.76,152.47,-0.464
5.77,152.67,-0.464
5.78,152.87,-0.464
5.79,153.07,-0.465
5.80,153.27,-0.466
5.81,153.47,-0.466
5.82,153.67,-0.467
5.83,153.87,-0.467
5.84,154.07,-0.468
5.85,154.27,-0.469
5.86,154.47,-0.469
5.87,154.67,-0.469
5.88,154.87,-0.470
5.89,155.07,-0.471
5.90,155.27,-0.471
5.91,155.47,-0.471
5.92,155.67,-0.472
5.93,155.87,-0.472
5.94,156.07,-0.473
5.95,156.27,-0.474
5.96,156.47,-0.474
5.97,156.67,-0.475
5.98,156.87,-0.475
5.99,157.07,-0.476
6.00,157.27,-0.476
6.01,157.47,-0.477
6.02,157.67,-0.477
6.03,157.87,-0.478
6.04,158.07,-0.478
6.05,158.27,-0.479
6.06,158.47,-0.479
6.07,158.67,-0.479
6.08,158.87,-0.480
6.09,159.07,-0.481
6.10,159.27,-0.481
6.11,159.47,-0.482
6.12,159.67,-0.482
6.13,159.87,-0.483
6.14,160.07,-0.483
6.15,160.27,-0.484
6.16,160.47,-0.484
6.17,160.68,-0.485
6.18,160.88,-0.485
6.19,161.07,-0.486
6.20,161.27,-0.486
6.21,161.47,-0.487
6.22,161.67,-0.487
6.23,161.87,-0.488
6.24,162.07,-0.488
6.25,162.27,-0.489
6.26,162.48,-0.489
6.27,162.68,-0.490
6.28,162.88,-0.490
6.29,163.08,-0.490
6.30,163.28,-0.491
6.31,163.48,-0.492
6.32,163.68,-0.492
6.33,163.88,-0.492
6.34,164.08,-0.493
6.35,164.28,-0.493
6.36,164.48,-0.494
6.37,164.68,-0.494
6.38,164.88,-0.495
6.39,165.08,-0.495
6.40,165.28,-0.495
6.41,165.48,-0.496
6.42,165.68,-0.496
6.43,165.88,-0.497
6.44,166.08,-0.497
6.45,166.28,-0.497
6.46,166.48,-0.498
6.47,166.68,-0.498
6.48,166.88,-0.498
6.49,167.08,-0.499
6.50,167.28,-0.499
6.51,167.48,-0.499
6.52,167.68,-0.500
6.53,167.88,-0.500
6.54,168.08,-0.500
6.55,168.28,-0.501
6.56,168.48,-0.501
6.57,168.68,-0.501
6.58,168.88,-0.502
6.59,169.08,-0.502
6.60,169.28,-0.502
6.61,169.48,-0.503
6.62,169.68,-0.503
6.63,169.88,-0.503
6.64,170.08,-0.504
6.65,170.28,-0.504
6.66,170.48,-0.505
6.67,170.68,-0.505
6.68,170.88,-0.506
6.69,171.08,-0.506
6.70,171.28,-0.506
6.71,171.48,-0.507
6.72,171.68,-0.507
6.73,171.88,-0.507
6.74,172.08,-0.508
6.75,172.28,-0.508
6.76,172.48,-0.508
6.77,172.68,-0.509
6.78,172.88,-0.510
6.79,173.08,-0.510
6.80,173.29,-0.511
6.81,173.48,-0.511
6.82,173.68,-0.512
6.83,173.88,-0.512
6.84,174.09,-0.512
6.85,174.29,-0.513
6.86,174.49,-0.513
6.87,174.69,-0.513
6.88,174.89,-0.514
6.89,175.09,-0.515
6.90,175.29,-0.515
6.91,175.49,-0.515
6.92,175.69,-0.515
6.93,175.89,-0.516
6.94,176.09,-0.516
6.95,176.29,-0.517
6.96,176.49,-0.517
6.97,176.69,-0.517
6.98,176.89,-0.518
6.99,177.09,-0.518
7.00,177.29,-0.518
7.01,177.49,-0.519
7.02,177.69,-0.519
7.03,177.89,-0.520
7.04,178.09,-0.520
7.05,178.29,-0.521
7.06,178.49,-0.521
7.07,178.69,-0.521
7.08,178.89,-0.522
7.09,179.09,-0.522
7.10,179.29,-0.523
7.11,179.49,-0.523
7.12,179.69,-0.523
7.13,179.89,-0.524
7.14,180.09,-0.525
7.15,180.29,-0.525
7.16,180.49,-0.526
7.17,180.69,-0.526
7.18,180.89,-0.527
7.19,181.09,-0.527
7.20,181.29,-0.527
7.21,181.49,-0.528
7.22,181.69,-0.528
7.23,181.89,-0.528
7.24,182.09,-0.529
7.25,182.29,-0.530
7.26,182.49,-0.530
7.27,182.69,-0.530
7.28,182.89,-0.530
7.29,183.09,-0.531
7.30,183.29,-0.531
7.31,183.49,-0.532
7.32,183.69,-0.532
7.33,183.89,-0.532
7.34,184.09,-0.533
7.35,184.29,-0.533
7.36,184.50,-0.533
7.37,184.69,-0.534
7.38,184.90,-0.534
7.39,185.10,-0.535
7.40,185.30,-0.535
7.41,185.50,-0.535
7.42,185.70,-0.536
7.43,185.90,-0.536
7.44,186.10,-0.536
7.45,186.30,-0.537
7.46,186.50,-0.537
7.47,186.70,-0.537
7.48,186.90,-0.538
7.49,187.10,-0.538
7.50,187.30,-0.538
7.51,187.50,-0.538
7.52,187.70,-0.539
7.53,187.90,-0.539
7.54,188.10,-0.539
7.55,188.30,-0.540
7.56,188.50,-0.540
7.57,188.70,-0.540
7.58,188.90,-0.541
7.59,189.10,-0.541
7.60,189.30,-0.541
7.61,189.50,-0.541
7.62,189.70,-0.542
7.63,189.90,-0.542
7.64,190.10,-0.542
7.65,190.30,-0.543
7.66,190.50,-0.543
7.67,190.70,-0.543
7.68,190.90,-0.543
7.69,191.10,-0.544
7.70,191.30,-0.544
7.71,191.50,-0.544
7.72,191.70,-0.544
7.73,191.90,-0.545
7.74,192.10,-0.545
7.75,192.30,-0.545
7.76,192.50,-0.546
7.77,192.70,-0.546
7.78,192.90,-0.546
7.79,193.10,-0.547
7.80,193.30,-0.547
7.81,193.50,-0.547
7.82,193.70,-0.547
7.83,193.90,-0.548
7.84,194.10,-0.548
7.85,194.30,-0.548
7.86,194.50,-0.548
7.87,194.70,-0.549
7.88,194.91,-0.549
7.89,195.11,-0.549
7.90,195.31,-0.550
7.91,195.51,-0.550
7.92,195.71,-0.550
7.93,195.91,-0.551
7.94,196.11,-0.551
7.95,196.31,-0.551
7.96,196.51,-0.551
7.97,196.71,-0.552
7.98,196.91,-0.552
7.99,197.11,-0.552
8.00,197.31,-0.553
8.01,197.51,-0.553
8.02,197.71,-0.553
8.03,197.91,-0.554
8.04,198.11,-0.554
8.05,198.31,-0.554
8.06,198.51,-0.554
8.07,198.71,-0.555
8.08,198.91,-0.555
8.09,199.11,-0.555
8.10,199.31,-0.555
8.11,199.51,-0.556
8.12,199.71,-0.556
8.13,199.91,-0.556
8.14,200.11,-0.557
8.15,200.31,-0.557
8.16,200.51,-0.557
8.17,200.71,-0.557
8.18,200.91,-0.558
8.19,201.11,-0.558
8.20,201.31,-0.558
8.21,201.51,-0.559
8.22,201.71,-0.559
8.23,201.91,-0.559
8.24,202.11,-0.560
8.25,202.31,-0.560
8.26,202.51,-0.560
8.27,202.71,-0.561
8.28,202.91,-0.561
8.29,203.11,-0.561
8.30,203.31,-0.561
8.31,203.51,-0.562
8.32,203.71,-0.562
8.33,203.91,-0.562
8.34,204.11,-0.563
8.35,204.31,-0.563
8.36,204.51,-0.563
8.37,204.71,-0.563
8.38,204.92,-0.564
8.39,205.12,-0.564
8.40,205.32,-0.565
8.41,205.52,-0.565
8.42,205.72,-0.565
8.43,205.92,-0.565
8.44,206.12,-0.566
8.45,206.32,-0.566
8.46,206.52,-0.566
8.47,206.72,-0.566
8.48,206.92,-0.567
8.49,207.12,-0.567
8.50,207.32,-0.567
8.51,207.52,-0.567
8.52,207.72,-0.568
8.53,207.92,-0.568
8.54,208.12,-0.568
8.55,208.32,-0.568
8.56,208.52,-0.569
8.57,208.72,-0.569
8.58,208.92,-0.569
8.59,209.12,-0.569
8.60,209.32,-0.570
8.61,209.52,-0.570
8.62,209.72,-0.570
8.63,209.92,-0.571
8.64,210.12,-0.571
8.65,210.32,-0.571
8.66,210.52,-0.572
8.67,210.72,-0.572
8.68,210.92,-0.572
8.69,211.12,-0.572
8.70,211.32,-0.573
8.71,211.52,-0.573
8.72,211.72,-0.573
8.73,211.92,-0.574
8.74,212.12,-0.574
8.75,212.32,-0.574
8.76,212.52,-0.574
8.77,212.72,-0.575
8.78,212.92,-0.575
8.79,213.12,-0.575
8.80,213.32,-0.576
8.81,213.52,-0.576
8.82,213.72,-0.576
8.83,213.92,-0.577
8.84,214.12,-0.577
8.85,214.32,-0.577
8.86,214.52,-0.577
8.87,214.72,-0.578
8.88,214.92,-0.578
8.89,215.12,-0.578
8.90,215.32,-0.579
8.91,215.52,-0.579
8.92,215.73,-0.579
8.93,215.93,-0.580
8.94,216.12,-0.580
8.95,216.33,-0.580
8.96,216.52,-0.581
8.97,216.73,-0.581
8.98,216.92,-0.581
8.99,217.13,-0.581
9.00,217.32,-0.582
9.01,217.53,-0.582
9.02,217.73,-0.582
9.03,217.93,-0.583
9.04,218.13,-0.583
9.05,218.33,-0.583
9.06,218.53,-0.584
9.07,218.73,-0.584
9.08,218.93,-0.584
9.09,219.13,-0.585
9.10,219.33,-0.585
9.11,219.53,-0.585
9.12,219.73,-0.585
9.13,219.93,-0.586
9.14,220.13,-0.586
9.15,220.33,-0.586
9.16,220.53,-0.587
9.17,220.73,-0.587
9.18,220.93,-0.587
9.19,221.13,-0.588
9.20,221.33,-0.588
9.21,221.53,-0.588
9.22,221.73,-0.589
9.23,221.93,-0.589
9.24,222.13,-0.589
9.25,222.33,-0.590
9.26,222.53,-0.590
9.27,222.73,-0.590
9.28,222.93,-0.591
9.29,223.13,-0.591
9.30,223.33,-0.591
9.31,223.53,-0.592
9.32,223.73,-0.592
9.33,223.93,-0.592
9.34,224.13,-0.593
9.35,224.33,-0.593
9.36,224.53,-0.593
9.37,224.73,-0.594
9.38,224.93,-0.594
9.39,225.13,-0.594
9.40,225.33,-0.595
9.41,225.53,-0.595
9.42,225.73,-0.596
9.43,225.93,-0.596
9.44,226.13,-0.597
9.45,226.33,-0.597
9.46,226.53,-0.597
9.47,226.73,-0.598
9.48,226.93,-0.599
9.49,227.13,-0.599
9.50,227.33,-0.599
9.51,227.53,-0.600
9.52,227.74,-0.600
9.53,227.93,-0.600
9.54,228.14,-0.601
9.55,228.33,-0.601
9.56,228.54,-0.601
9.57,228.74,-0.602
9.58,228.94,-0.602
9.59,229.14,-0.603
9.60,229.34,-0.603
9.61,229.54,-0.603
9.62,229.74,-0.604
9.63,229.94,-0.604
9.64,230.14,-0.605
9.65,230.34,-0.605
9.66,230.54,-0.606
9.67,230.74,-0.606
9.68,230.94,-0.607
9.69,231.14,-0.607
9.70,231.34,-0.608
9.71,231.54,-0.608
9.72,231.74,-0.609
9.73,231.94,-0.609
9.74,232.14,-0.609
9.75,232.34,-0.610
9.76,232.54,-0.611
9.77,232.74,-0.611
9.78,232.94,-0.612
9.79,233.14,-0.612
9.80,233.34,-0.613
9.81,233.54,-0.613
9.82,233.74,-0.613
9.83,233.94,-0.614
9.84,234.14,-0.615
9.85,234.34,-0.615
9.86,234.54,-0.615
9.87,234.74,-0.616
9.88,234.94,-0.617
9.89,235.14,-0.617
9.90,235.34,-0.618
9.91,235.54,-0.618
9.92,235.74,-0.619
9.93,235.94,-0.619
9.94,236.14,-0.620
9.95,236.34,-0.621
9.96,236.54,-0.621
9.97,236.74,-0.622
9.98,236.94,-0.622
9.99,237.14,-0.623
10.00,237.34,-0.623
10.01,237.54,-0.624
10.02,237.74,-0.624
10.03,237.94,-0.626
10.04,238.14,-0.627
10.05,238.34,-0.628
10.06,238.54,-0.629
10.07,238.74,-0.630
10.08,238.94,-0.630
10.09,239.14,-0.630
10.10,239.34,-0.632
10.11,239.54,-0.632
10.12,239.74,-0.633
10.13,239.94,-0.634
10.14,240.14,-0.635
10.15,240.34,-0.635
10.16,240.54,-0.636
10.17,240.74,-0.638
10.18,240.94,-0.638
10.19,241.14,-0.639
10.20,241.34,-0.639
10.21,241.54,-0.640
10.22,241.74,-0.641
10.23,241.94,-0.642
10.24,242.14,-0.643
10.25,242.34,-0.644
10.26,242.54,-0.646
10.27,242.74,-0.646
10.28,242.94,-0.648
10.29,243.14,-0.648
10.30,243.35,-0.649
10.31,243.54,-0.650
10.32,243.75,-0.652
10.33,243.95,-0.652
10.34,244.15,-0.653
10.35,244.35,-0.654
10.36,244.54,-0.656
10.37,244.75,-0.657
10.38,244.95,-0.658
10.39,245.14,-0.659
10.40,245.35,-0.659
10.41,245.55,-0.660
10.42,245.75,-0.661
10.43,245.95,-0.662
10.44,246.15,-0.664
10.45,246.35,-0.666
10.46,246.55,-0.666
10.47,246.75,-0.668
10.48,246.95,-0.669
10.49,247.15,-0.670
10.50,247.35,-0.671
10.51,247.55,-0.672
10.52,247.75,-0.673
10.53,247.95,-0.675
10.54,248.15,-0.677
10.55,248.35,-0.678
10.56,248.55,-0.679
10.57,248.75,-0.680
10.58,248.95,-0.683
10.59,249.15,-0.685
10.60,249.35,-0.686
10.61,249.55,-0.688
10.62,249.75,-0.689
10.63,249.95,-0.691
10.64,250.15,-0.693
10.65,250.35,-0.694
10.66,250.55,-0.696
10.67,250.75,-0.696
10.68,250.95,-0.698
10.69,251.15,-0.700
10.70,251.35,-0.702
10.71,251.55,-0.704
10.72,251.75,-0.706
10.73,251.95,-0.708
10.74,252.15,-0.711
10.75,252.35,-0.713
10.76,252.54,-0.714
10.77,252.75,-0.717
10.78,252.95,-0.720
10.79,253.15,-0.722
10.80,253.34,-0.723
10.81,253.55,-0.725
10.82,253.75,-0.726
10.83,253.95,-0.730
10.84,254.15,-0.731
10.85,254.35,-0.734
10.86,254.54,-0.737
10.87,254.74,-0.740
10.88,254.94,-0.741
10.89,255.14,-0.743
10.90,255.34,-0.745
10.91,255.54,-0.748
10.92,255.74,-0.750
10.93,255.94,-0.754
10.94,256.14,-0.757
10.95,256.34,-0.760
10.96,256.54,-0.761
10.97,256.74,-0.764
10.98,256.94,-0.767
10.99,257.14,-0.770
11.00,257.34,-0.774
11.01,257.54,-0.776
11.02,257.74,-0.778
11.03,257.94,-0.781
11.04,258.14,-0.785
11.05,258.34,-0.789
11.06,258.54,-0.791
11.07,258.74,-0.795
11.08,258.94,-0.799
11.09,259.14,-0.801
11.10,259.34,-0.804
11.11,259.54,-0.808
11.12,259.74,-0.812
11.13,259.94,-0.815
11.14,260.14,-0.821
11.15,260.34,-0.823
11.16,260.54,-0.826
11.17,260.74,-0.831
11.18,260.94,-0.835
11.19,261.14,-0.840
11.20,261.33,-0.842
11.21,261.53,-0.846
11.22,261.73,-0.853
11.23,261.93,-0.857
11.24,262.13,-0.861
11.25,262.33,-0.866
11.26,262.53,-0.869
11.27,262.73,-0.875
11.28,262.93,-0.878
11.29,263.13,-0.881
11.30,263.33,-0.891
11.31,263.53,-0.891
11.32,263.73,-0.896
11.33,263.93,-0.903
11.34,264.13,-0.909
11.35,264.33,-0.913
11.36,264.52,-0.918
11.37,264.72,-0.922
11.38,264.92,-0.928
11.39,265.12,-0.933
11.40,265.32,-0.940
11.41,265.52,-0.944
11.42,265.72,-0.951
11.43,265.92,-0.956
11.44,266.12,-0.964
11.45,266.32,-0.969
11.46,266.52,-0.975
11.47,266.72,-0.983
11.48,266.92,-0.989
11.49,267.11,-0.995
11.50,267.31,-1.002
11.51,267.51,-1.007
11.52,267.71,-1.015
11.53,267.91,-1.023
11.54,268.11,-1.028
11.55,268.31,-1.037
11.56,268.51,-1.044
11.57,268.71,-1.049
11.58,268.91,-1.059
11.59,269.11,-1.066
11.60,269.30,-1.074
11.61,269.50,-1.081
11.62,269.70,-1.089
11.63,269.90,-1.098
11.64,270.10,-1.103
11.65,270.30,-1.112
11.66,270.50,-1.122
11.67,270.70,-1.129
11.68,270.89,-1.139
11.69,271.09,-1.147
11.70,271.29,-1.155
11.71,271.49,-1.163
11.72,271.69,-1.174
11.73,271.89,-1.183
11.74,272.09,-1.192
11.75,272.29,-1.200
11.76,272.48,-1.209
11.77,272.68,-1.220
11.78,272.88,-1.230
11.79,273.08,-1.238
11.80,273.28,-1.249
11.81,273.48,-1.258
11.82,273.67,-1.269
11.83,273.87,-1.279
11.84,274.07,-1.289
11.85,274.27,-1.298
11.86,274.47,-1.310
11.87,274.67,-1.320
11.88,274.87,-1.329
11.89,275.06,-1.339
11.90,275.26,-1.349
11.91,275.46,-1.361
11.92,275.66,-1.368
11.93,275.86,-1.381
11.94,276.05,-1.391
11.95,276.25,-1.400
11.96,276.45,-1.411
11.97,276.65,-1.419
11.98,276.85,-1.429
11.99,277.05,-1.437
12.00,277.24,-1.447
12.01,277.44,-1.454
12.02,277.64,-1.463
12.03,277.84,-1.469
12.04,278.04,-1.476
12.05,278.24,-1.483
12.06,278.44,-1.489
12.07,278.64,-1.495
12.08,278.84,-1.499
12.09,279.04,-1.502
12.10,279.23,-1.505
12.11,279.43,-1.509
12.12,279.63,-1.509
12.13,279.83,-1.511
12.14,280.03,-1.511
12.15,280.23,-1.510
12.16,280.43,-1.509
12.17,280.63,-1.507
12.18,280.83,-1.502
12.19,281.03,-1.499
12.20,281.23,-1.488
12.21,281.43,-1.477
12.22,281.64,-1.466
12.23,281.84,-1.455
12.24,282.04,-1.439
12.25,282.24,-1.423
12.26,282.44,-1.406
12.27,282.65,-1.386
12.28,282.85,-1.365
12.29,283.05,-1.340
12.30,283.25,-1.315
12.31,283.46,-1.287
12.32,283.66,-1.258
12.33,283.87,-1.226
12.34,284.07,-1.194
12.35,284.28,-1.164
12.36,284.48,-1.130
12.37,284.69,-1.097
12.38,284.89,-1.069
12.39,285.10,-1.033
12.40,285.31,-1.005
12.41,285.51,-0.981
12.42,285.72,-0.951
12.43,285.92,-0.928
12.44,286.13,-0.907
12.45,286.33,-0.887
12.46,286.54,-0.868
12.47,286.74,-0.851
12.48,286.95,-0.834
12.49,287.15,-0.823
12.50,287.35,-0.812
12.51,287.56,-0.799
12.52,287.76,-0.789
12.53,287.97,-0.782
12.54,288.17,-0.776
12.55,288.37,-0.767
12.56,288.57,-0.761
12.57,288.77,-0.756
12.58,288.98,-0.752
12.59,289.18,-0.750
12.60,289.38,-0.745
12.61,289.58,-0.741
12.62,289.78,-0.738
12.63,289.98,-0.737
12.64,290.19,-0.735
12.65,290.39,-0.733
12.66,290.59,-0.732
12.67,290.79,-0.729
12.68,290.99,-0.728
12.69,291.19,-0.728
12.70,291.39,-0.727
12.71,291.59,-0.726
12.72,291.79,-0.726
12.73,291.99,-0.726
12.74,292.19,-0.725
12.75,292.39,-0.725
12.76,292.59,-0.725
12.77,292.79,-0.724
12.78,292.99,-0.724
12.79,293.19,-0.724
12.80,293.39,-0.724
12.81,293.59,-0.724
12.82,293.80,-0.724
12.83,294.00,-0.724
12.84,294.20,-0.724
12.85,294.40,-0.724
12.86,294.60,-0.724
12.87,294.80,-0.724
12.88,295.00,-0.724
12.89,295.20,-0.724
12.90,295.40,-0.724
12.91,295.60,-0.724
12.92,295.80,-0.724
12.93,296.00,-0.724
12.94,296.20,-0.724
12.95,296.40,-0.725
12.96,296.60,-0.725
12.97,296.80,-0.725
12.98,297.00,-0.725
12.99,297.20,-0.725
13.00,297.37,-0.725

[step]
Ramp 20.00 °C/min to 40.00 °C
Time,Temperature,Heat Flow (Normalized)
min,°C,W/g
13.00,297.40,-0.725
13.01,297.60,-0.726
13.02,297.80,-0.726
13.03,297.99,-0.728
13.04,298.17,-0.735
13.05,298.34,-0.737
13.06,298.49,-0.719
13.07,298.63,-0.671
13.08,298.74,-0.609
13.09,298.82,-0.530
13.10,298.87,-0.441
13.11,298.89,-0.352
13.12,298.89,-0.263
13.13,298.85,-0.181
13.14,298.80,-0.104
13.15,298.73,-0.033
13.16,298.64,0.034
13.17,298.53,0.096
13.18,298.42,0.153
13.19,298.29,0.205
13.20,298.16,0.251
13.21,298.01,0.296
13.22,297.86,0.333
13.23,297.70,0.370
13.24,297.54,0.398
13.25,297.37,0.427
13.26,297.20,0.449
13.27,297.02,0.471
13.28,296.84,0.491
13.29,296.66,0.508
13.30,296.48,0.522
13.31,296.29,0.536
13.32,296.10,0.546
13.33,295.91,0.554
13.34,295.72,0.567
13.35,295.53,0.574
13.36,295.34,0.582
13.37,295.15,0.587
13.38,294.95,0.592
13.39,294.75,0.599
13.40,294.56,0.602
13.41,294.36,0.606
13.42,294.17,0.607
13.43,293.97,0.608
13.44,293.77,0.613
13.45,293.57,0.615
13.46,293.37,0.616
13.47,293.18,0.617
13.48,292.98,0.619
13.49,292.78,0.620
13.50,292.58,0.621
13.51,292.38,0.621
13.52,292.18,0.621
13.53,291.98,0.622
13.54,291.78,0.622
13.55,291.59,0.622
13.56,291.39,0.622
13.57,291.19,0.623
13.58,290.99,0.623
13.59,290.79,0.623
13.60,290.59,0.624
13.61,290.39,0.624
13.62,290.19,0.624
13.63,289.99,0.624
13.64,289.80,0.624
13.65,289.60,0.624
13.66,289.40,0.624
13.67,289.20,0.624
13.68,289.00,0.624
13.69,288.80,0.624
13.70,288.60,0.624
13.71,288.40,0.624
13.72,288.20,0.624
13.73,288.01,0.624
13.74,287.81,0.624
13.75,287.61,0.624
13.76,287.41,0.624
13.77,287.21,0.624
13.78,287.01,0.624
13.79,286.81,0.624
13.80,286.61,0.624
13.81,286.41,0.624
13.82,286.22,0.624
13.83,286.02,0.624
13.84,285.82,0.624
13.85,285.62,0.624
13.86,285.42,0.624
13.87,285.22,0.623
13.88,285.02,0.623
13.89,284.82,0.623
13.90,284.62,0.623
13.91,284.43,0.623
13.92,284.23,0.623
13.93,284.03,0.623
13.94,283.83,0.623
13.95,283.63,0.623
13.96,283.43,0.623
13.97,283.23,0.622
13.98,283.03,0.622
13.99,282.83,0.622
14.00,282.63,0.622
14.01,282.44,0.622
14.02,282.24,0.622
14.03,282.04,0.622
14.04,281.84,0.622
14.05,281.64,0.622
14.06,281.44,0.622
14.07,281.24,0.621
14.08,281.04,0.621
14.09,280.84,0.621
14.10,280.64,0.621
14.11,280.45,0.621
14.12,280.25,0.621
14.13,280.05,0.621
14.14,279.85,0.621
14.15,279.65,0.621
14.16,279.45,0.620
14.17,279.25,0.620
14.18,279.05,0.620
14.19,278.85,0.620
14.20,278.65,0.620
14.21,278.46,0.620
14.22,278.26,0.620
14.23,278.06,0.620
14.24,277.86,0.620
14.25,277.66,0.619
14.26,277.46,0.619
14.27,277.26,0.619
14.28,277.06,0.619
14.29,276.86,0.619
14.30,276.66,0.619
14.31,276.46,0.619
14.32,276.26,0.619
14.33,276.06,0.618
14.34,275.87,0.618
14.35,275.67,0.618
14.36,275.47,0.618
14.37,275.27,0.618
14.38,275.07,0.618
14.39,274.87,0.618
14.40,274.67,0.618
14.41,274.47,0.618
14.42,274.27,0.617
14.43,274.07,0.617
14.44,273.87,0.617
14.45,273.67,0.617
14.46,273.47,0.617
14.47,273.27,0.617
14.48,273.07,0.617
14.49,272.88,0.617
14.50,272.68,0.616
14.51,272.48,0.616
14.52,272.28,0.616
14.53,272.08,0.616
14.54,271.88,0.616
14.55,271.68,0.616
14.56,271.48,0.616
14.57,271.28,0.616
14.58,271.08,0.615
14.59,270.88,0.615
14.60,270.68,0.615
14.61,270.48,0.615
14.62,270.28,0.615
14.63,270.08,0.615
14.64,269.88,0.615
14.65,269.68,0.615
14.66,269.48,0.614
14.67,269.28,0.614
14.68,269.09,0.614
14.69,268.88,0.614
14.70,268.68,0.614
14.71,268.49,0.614
14.72,268.29,0.614
14.73,268.09,0.614
14.74,267.89,0.613
14.75,267.69,0.613
14.76,267.49,0.613
14.77,267.29,0.613
14.78,267.09,0.613
14.79,266.89,0.613
14.80,266.69,0.613
14.81,266.49,0.613
14.82,266.29,0.612
14.83,266.09,0.612
14.84,265.89,0.612
14.85,265.69,0.612
14.86,265.49,0.612
14.87,265.29,0.612
14.88,265.09,0.612
14.89,264.89,0.612
14.90,264.69,0.612
14.91,264.50,0.612
14.92,264.30,0.611
14.93,264.10,0.611
14.94,263.90,0.611
14.95,263.70,0.611
14.96,263.50,0.611
14.97,263.30,0.611
14.98,263.10,0.611
14.99,262.90,0.611
15.00,262.70,0.611
15.01,262.50,0.610
15.02,262.30,0.610
15.03,262.10,0.610
15.04,261.90,0.610
15.05,261.70,0.610
15.06,261.50,0.610
15.07,261.30,0.610
15.08,261.10,0.610
15.09,260.90,0.610
15.10,260.70,0.610
15.11,260.50,0.609
15.12,260.30,0.609
15.13,260.10,0.609
15.14,259.90,0.609
15.15,259.70,0.609
15.16,259.50,0.609
15.17,259.30,0.609
15.18,259.10,0.609
15.19,258.90,0.609
15.20,258.70,0.608
15.21,258.51,0.608
15.22,258.31,0.608
15.23,258.11,0.608
15.24,257.91,0.608
15.25,257.71,0.608
15.26,257.51,0.608
15.27,257.31,0.608
15.28,257.11,0.608
15.29,256.91,0.608
15.30,256.71,0.608
15.31,256.51,0.607
15.32,256.31,0.607
15.33,256.11,0.607
15.34,255.91,0.607
15.35,255.71,0.607
15.36,255.51,0.607
15.37,255.31,0.607
15.38,255.11,0.607
15.39,254.91,0.607
15.40,254.71,0.607
15.41,254.51,0.606
15.42,254.31,0.606
15.43,254.11,0.606
15.44,253.91,0.606
15.45,253.71,0.606
15.46,253.51,0.606
15.47,253.31,0.606
15.48,253.11,0.606
15.49,252.91,0.606
15.50,252.71,0.605
15.51,252.51,0.605
15.52,252.31,0.605
15.53,252.11,0.605
15.54,251.91,0.605
15.55,251.71,0.605
15.56,251.51,0.605
15.57,251.32,0.605
15.58,251.12,0.605
15.59,250.92,0.605
15.60,250.72,0.604
15.61,250.52,0.604
15.62,250.32,0.604
15.63,250.12,0.604
15.64,249.92,0.604
15.65,249.72,0.604
15.66,249.52,0.604
15.67,249.32,0.604
15.68,249.12,0.604
15.69,248.92,0.604
15.70,248.72,0.604
15.71,248.52,0.603
15.72,248.32,0.603
15.73,248.12,0.603
15.74,247.92,0.603
15.75,247.72,0.603
15.76,247.52,0.603
15.77,247.32,0.603
15.78,247.12,0.603
15.79,246.92,0.603
15.80,246.72,0.603
15.81,246.52,0.603
15.82,246.32,0.603
15.83,246.12,0.603
15.84,245.92,0.603
15.85,245.72,0.603
15.86,245.52,0.603
15.87,245.33,0.603
15.88,245.13,0.603
15.89,244.93,0.603
15.90,244.73,0.603
15.91,244.53,0.603
15.92,244.33,0.603
15.93,244.13,0.603
15.94,243.93,0.603
15.95,243.73,0.603
15.96,243.53,0.603
15.97,243.33,0.603
15.98,243.13,0.604
15.99,242.93,0.604
16.00,242.73,0.604
16.01,242.53,0.604
16.02,242.33,0.605
16.03,242.13,0.605
16.04,241.93,0.606
16.05,241.73,0.606
16.06,241.53,0.606
16.07,241.33,0.607
16.08,241.13,0.609
16.09,240.93,0.610
16.10,240.73,0.611
16.11,240.53,0.613
16.12,240.33,0.615
16.13,240.14,0.617
16.14,239.94,0.622
16.15,239.74,0.623
16.16,239.54,0.626
16.17,239.34,0.630
16.18,239.14,0.634
16.19,238.94,0.638
16.20,238.74,0.640
16.21,238.54,0.645
16.22,238.34,0.648
16.23,238.14,0.654
16.24,237.94,0.657
16.25,237.74,0.663
16.26,237.55,0.668
16.27,237.35,0.672
16.28,237.15,0.678
16.29,236.95,0.685
16.30,236.75,0.693
16.31,236.55,0.698
16.32,236.35,0.702
16.33,236.16,0.714
16.34,235.96,0.721
16.35,235.76,0.729
16.36,235.56,0.737
16.37,235.36,0.747
16.38,235.16,0.755
16.39,234.97,0.767
16.40,234.77,0.778
16.41,234.57,0.789
16.42,234.37,0.803
16.43,234.17,0.815
16.44,233.98,0.826
16.45,233.78,0.842
16.46,233.58,0.857
16.47,233.38,0.875
16.48,233.19,0.893
16.49,232.99,0.910
16.50,232.80,0.931
16.51,232.60,0.950
16.52,232.40,0.974
16.53,232.21,0.998
16.54,232.01,1.021
16.55,231.81,1.051
16.56,231.62,1.079
16.57,231.43,1.108
16.58,231.23,1.141
16.59,231.04,1.175
16.60,230.84,1.211
16.61,230.65,1.248
16.62,230.46,1.288
16.63,230.26,1.330
16.64,230.07,1.374
16.65,229.88,1.421
16.66,229.69,1.469
16.67,229.49,1.518
16.68,229.30,1.571
16.69,229.11,1.624
16.70,228.92,1.679
16.71,228.73,1.735
16.72,228.54,1.792
16.73,228.35,1.849
16.74,228.16,1.906
16.75,227.98,1.962
16.76,227.79,2.020
16.77,227.60,2.072
16.78,227.41,2.123
16.79,227.22,2.165
16.80,227.03,2.209
16.81,226.84,2.254
16.82,226.65,2.293
16.83,226.46,2.317
16.84,226.27,2.337
16.85,226.08,2.350
16.86,225.88,2.357
16.87,225.69,2.355
16.88,225.49,2.346
16.89,225.30,2.327
16.90,225.10,2.305
16.91,224.90,2.266
16.92,224.70,2.228
16.93,224.49,2.178
16.94,224.29,2.122
16.95,224.08,2.063
16.96,223.88,1.997
16.97,223.67,1.924
16.98,223.46,1.821
16.99,223.25,1.728
17.00,223.04,1.696
17.01,222.82,1.627
17.02,222.61,1.552
17.03,222.40,1.479
17.04,222.19,1.412
17.05,221.97,1.348
17.06,221.76,1.289
17.07,221.55,1.230
17.08,221.34,1.177
17.09,221.13,1.128
17.10,220.92,1.088
17.11,220.71,1.044
17.12,220.50,1.008
17.13,220.29,0.979
17.14,220.08,0.949
17.15,219.87,0.921
17.16,219.66,0.897
17.17,219.45,0.877
17.18,219.25,0.859
17.19,219.04,0.840
17.20,218.84,0.827
17.21,218.63,0.812
17.22,218.43,0.800
17.23,218.22,0.788
17.24,218.02,0.778
17.25,217.82,0.767
17.26,217.61,0.760
17.27,217.41,0.750
17.28,217.21,0.743
17.29,217.01,0.736
17.30,216.81,0.731
17.31,216.60,0.725
17.32,216.40,0.718
17.33,216.20,0.712
17.34,216.00,0.708
17.35,215.80,0.704
17.36,215.60,0.701
17.37,215.40,0.697
17.38,215.20,0.693
17.39,214.99,0.689
17.40,214.79,0.685
17.41,214.59,0.682
17.42,214.39,0.679
17.43,214.19,0.677
17.44,213.99,0.675
17.45,213.79,0.673
17.46,213.59,0.670
17.47,213.39,0.667
17.48,213.19,0.664
17.49,212.99,0.663
17.50,212.79,0.661
17.51,212.59,0.659
17.52,212.39,0.658
17.53,212.19,0.657
17.54,211.99,0.655
17.55,211.79,0.652
17.56,211.59,0.652
17.57,211.39,0.649
17.58,211.19,0.647
17.59,210.99,0.646
17.60,210.79,0.645
17.61,210.59,0.644
17.62,210.39,0.643
17.63,210.19,0.641
17.64,209.99,0.640
17.65,209.79,0.639
17.66,209.59,0.638
17.67,209.39,0.637
17.68,209.19,0.637
17.69,208.99,0.636
17.70,208.79,0.635
17.71,208.59,0.634
17.72,208.39,0.632
17.73,208.19,0.631
17.74,207.99,0.631
17.75,207.79,0.630
17.76,207.59,0.629
17.77,207.39,0.628
17.78,207.19,0.628
17.79,206.99,0.626
17.80,206.79,0.625
17.81,206.59,0.625
17.82,206.39,0.624
17.83,206.19,0.624
17.84,205.99,0.623
17.85,205.79,0.622
17.86,205.59,0.622
17.87,205.39,0.620
17.88,205.19,0.620
17.89,204.99,0.619
17.90,204.79,0.618
17.91,204.59,0.617
17.92,204.39,0.617
17.93,204.19,0.617
17.94,203.99,0.616
17.95,203.79,0.615
17.96,203.59,0.613
17.97,203.39,0.613
17.98,203.19,0.612
17.99,202.99,0.612
18.00,202.79,0.611
18.01,202.59,0.610
18.02,202.39,0.610
18.03,202.19,0.610
18.04,201.99,0.609
18.05,201.79,0.609
18.06,201.59,0.609
18.07,201.39,0.608
18.08,201.19,0.607
18.09,200.99,0.606
18.10,200.79,0.605
18.11,200.59,0.604
18.12,200.39,0.604
18.13,200.19,0.603
18.14,199.99,0.603
18.15,199.79,0.603
18.16,199.59,0.602
18.17,199.39,0.602
18.18,199.20,0.601
18.19,199.00,0.601
18.20,198.80,0.600
18.21,198.60,0.599
18.22,198.40,0.599
18.23,198.20,0.599
18.24,198.00,0.598
18.25,197.80,0.598
18.26,197.60,0.597
18.27,197.40,0.597
18.28,197.20,0.596
18.29,197.00,0.596
18.30,196.80,0.595
18.31,196.60,0.595
18.32,196.40,0.594
18.33,196.20,0.594
18.34,196.00,0.593
18.35,195.80,0.593
18.36,195.60,0.592
18.37,195.40,0.592
18.38,195.20,0.591
18.39,195.00,0.591
18.40,194.80,0.591
18.41,194.60,0.590
18.42,194.40,0.590
18.43,194.20,0.590
18.44,194.00,0.589
18.45,193.80,0.589
18.46,193.60,0.588
18.47,193.40,0.588
18.48,193.20,0.588
18.49,193.00,0.587
18.50,192.80,0.587
18.51,192.60,0.586
18.52,192.40,0.586
18.53,192.20,0.586
18.54,192.00,0.585
18.55,191.80,0.585
18.56,191.60,0.585
18.57,191.40,0.584
18.58,191.20,0.584
18.59,191.00,0.583
18.60,190.80,0.583
18.61,190.60,0.582
18.62,190.41,0.582
18.63,190.20,0.582
18.64,190.01,0.581
18.65,189.81,0.581
18.66,189.61,0.580
18.67,189.41,0.580
18.68,189.21,0.579
18.69,189.01,0.579
18.70,188.81,0.578
18.71,188.61,0.578
18.72,188.41,0.577
18.73,188.21,0.577
18.74,188.01,0.577
18.75,187.81,0.577
18.76,187.61,0.576
18.77,187.41,0.576
18.78,187.21,0.576
18.79,187.01,0.575
18.80,186.81,0.575
18.81,186.61,0.575
18.82,186.41,0.574
18.83,186.21,0.574
18.84,186.01,0.574
18.85,185.81,0.573
18.86,185.61,0.573
18.87,185.41,0.572
18.88,185.21,0.572
18.89,185.01,0.572
18.90,184.81,0.571
18.91,184.61,0.571
18.92,184.41,0.571
18.93,184.21,0.570
18.94,184.01,0.570
18.95,183.81,0.570
18.96,183.61,0.569
18.97,183.41,0.569
18.98,183.21,0.568
18.99,183.01,0.568
19.00,182.81,0.568
19.01,182.61,0.568
19.02,182.41,0.567
19.03,182.21,0.566
19.04,182.01,0.566
19.05,181.81,0.566
19.06,181.61,0.565
19.07,181.41,0.565
19.08,181.22,0.565
19.09,181.02,0.564
19.10,180.82,0.564
19.11,180.62,0.564
19.12,180.42,0.563
19.13,180.22,0.563
19.14,180.02,0.562
19.15,179.82,0.562
19.16,179.62,0.561
19.17,179.42,0.561
19.18,179.22,0.561
19.19,179.02,0.560
19.20,178.82,0.560
19.21,178.62,0.560
19.22,178.42,0.560
19.23,178.22,0.559
19.24,178.02,0.559
19.25,177.82,0.559
19.26,177.62,0.558
19.27,177.42,0.558
19.28,177.22,0.558
19.29,177.02,0.557
19.30,176.82,0.557
19.31,176.62,0.557
19.32,176.42,0.556
19.33,176.22,0.556
19.34,176.02,0.556
19.35,175.82,0.555
19.36,175.62,0.555
19.37,175.42,0.555
19.38,175.22,0.554
19.39,175.02,0.554
19.40,174.82,0.554
19.41,174.62,0.554
19.42,174.42,0.553
19.43,174.22,0.553
19.44,174.02,0.553
19.45,173.82,0.552
19.46,173.63,0.552
19.47,173.43,0.552
19.48,173.23,0.551
19.49,173.03,0.551
19.50,172.83,0.551
19.51,172.63,0.550
19.52,172.43,0.550
19.53,172.23,0.550
19.54,172.03,0.549
19.55,171.83,0.549
19.56,171.63,0.549
19.57,171.43,0.549
19.58,171.23,0.548
19.59,171.03,0.548
19.60,170.83,0.547
19.61,170.63,0.547
19.62,170.43,0.547
19.63,170.23,0.546
19.64,170.03,0.546
19.65,169.83,0.546
19.66,169.63,0.545
19.67,169.43,0.545
19.68,169.23,0.545
19.69,169.03,0.545
19.70,168.83,0.544
19.71,168.63,0.544
19.72,168.43,0.544
19.73,168.23,0.543
19.74,168.03,0.543
19.75,167.83,0.543
19.76,167.63,0.543
19.77,167.43,0.542
19.78,167.23,0.542
19.79,167.03,0.541
19.80,166.83,0.541
19.81,166.63,0.541
19.82,166.43,0.541
19.83,166.23,0.540
19.84,166.03,0.539
19.85,165.84,0.539
19.86,165.63,0.539
19.87,165.44,0.539
19.88,165.24,0.539
19.89,165.04,0.538
19.90,164.84,0.538
19.91,164.64,0.538
19.92,164.44,0.538
19.93,164.24,0.537
19.94,164.04,0.537
19.95,163.84,0.537
19.96,163.64,0.536
19.97,163.44,0.536
19.98,163.24,0.536
19.99,163.04,0.536
20.00,162.84,0.536
20.01,162.64,0.535
20.02,162.44,0.535
20.03,162.24,0.535
20.04,162.04,0.535
20.05,161.84,0.534
20.06,161.64,0.534
20.07,161.44,0.534
20.08,161.24,0.533
20.09,161.04,0.533
20.10,160.84,0.533
20.11,160.64,0.532
20.12,160.44,0.532
20.13,160.24,0.532
20.14,160.04,0.532
20.15,159.84,0.531
20.16,159.64,0.531
20.17,159.44,0.531
20.18,159.25,0.531
20.19,159.04,0.530
20.20,158.85,0.530
20.21,158.65,0.530
20.22,158.45,0.530
20.23,158.25,0.529
20.24,158.05,0.529
20.25,157.85,0.529
20.26,157.65,0.528
20.27,157.45,0.528
20.28,157.25,0.528
20.29,157.05,0.528
20.30,156.85,0.527
20.31,156.65,0.527
20.32,156.45,0.527
20.33,156.25,0.526
20.34,156.05,0.526
20.35,155.85,0.525
20.36,155.65,0.525
20.37,155.45,0.525
20.38,155.25,0.525
20.39,155.05,0.524
20.40,154.85,0.524
20.41,154.65,0.524
20.42,154.45,0.523
20.43,154.25,0.523
20.44,154.05,0.523
20.45,153.85,0.522
20.46,153.65,0.522
20.47,153.45,0.522
20.48,153.25,0.521
20.49,153.05,0.521
20.50,152.85,0.520
20.51,152.66,0.520
20.52,152.45,0.520
20.53,152.26,0.520
20.54,152.06,0.519
20.55,151.86,0.519
20.56,151.66,0.519
20.57,151.46,0.518
20.58,151.26,0.518
20.59,151.06,0.518
20.60,150.86,0.517
20.61,150.66,0.517
20.62,150.46,0.517
20.63,150.26,0.516
20.64,150.06,0.516
20.65,149.86,0.515
20.66,149.66,0.515
20.67,149.46,0.515
20.68,149.26,0.514
20.69,149.06,0.514
20.70,148.86,0.514
20.71,148.66,0.513
20.72,148.46,0.513
20.73,148.26,0.513
20.74,148.06,0.513
20.75,147.86,0.512
20.76,147.66,0.512
20.77,147.46,0.512
20.78,147.26,0.511
20.79,147.06,0.511
20.80,146.86,0.511
20.81,146.66,0.510
20.82,146.46,0.510
20.83,146.26,0.510
20.84,146.06,0.509
20.85,145.86,0.509
20.86,145.66,0.509
20.87,145.47,0.509
20.88,145.27,0.508
20.89,145.07,0.508
20.90,144.87,0.508
20.91,144.67,0.507
20.92,144.47,0.507
20.93,144.27,0.507
20.94,144.07,0.506
20.95,143.87,0.506
20.96,143.67,0.506
20.97,143.47,0.506
20.98,143.27,0.505
20.99,143.07,0.505
21.00,142.87,0.505
21.01,142.67,0.505
21.02,142.47,0.504
21.03,142.27,0.504
21.04,142.07,0.504
21.05,141.87,0.503
21.06,141.67,0.503
21.07,141.47,0.503
21.08,141.27,0.503
21.09,141.07,0.502
21.10,140.87,0.502
21.11,140.67,0.502
21.12,140.47,0.501
21.13,140.27,0.501
21.14,140.07,0.501
21.15,139.87,0.501
21.16,139.67,0.500
21.17,139.47,0.500
21.18,139.28,0.500
21.19,139.08,0.499
21.20,138.88,0.499
21.21,138.68,0.499
21.22,138.48,0.499
21.23,138.28,0.498
21.24,138.08,0.498
21.25,137.88,0.498
21.26,137.68,0.497
21.27,137.48,0.497
21.28,137.28,0.497
21.29,137.08,0.497
21.30,136.88,0.496
21.31,136.68,0.496
21.32,136.48,0.496
21.33,136.28,0.495
21.34,136.08,0.495
21.35,135.88,0.495
21.36,135.68,0.495
21.37,135.48,0.494
21.38,135.28,0.494
21.39,135.08,0.494
21.40,134.88,0.494
21.41,134.68,0.493
21.42,134.48,0.493
21.43,134.28,0.493
21.44,134.08,0.492
21.45,133.88,0.492
21.46,133.68,0.492
21.47,133.48,0.491
21.48,133.29,0.491
21.49,133.09,0.491
21.50,132.89,0.491
21.51,132.69,0.490
21.52,132.49,0.490
21.53,132.29,0.490
21.54,132.09,0.490
21.55,131.89,0.489
21.56,131.69,0.489
21.57,131.49,0.489
21.58,131.29,0.489
21.59,131.09,0.488
21.60,130.89,0.488
21.61,130.69,0.488
21.62,130.49,0.487
21.63,130.29,0.487
21.64,130.09,0.487
21.65,129.89,0.487
21.66,129.69,0.487
21.67,129.49,0.486
21.68,129.29,0.486
21.69,129.09,0.486
21.70,128.89,0.485
21.71,128.69,0.485
21.72,128.49,0.485
21.73,128.29,0.484
21.74,128.09,0.484
21.75,127.89,0.484
21.76,127.69,0.483
21.77,127.49,0.483
21.78,127.29,0.483
21.79,127.09,0.483
21.80,126.89,0.482
21.81,126.69,0.482
21.82,126.49,0.482
21.83,126.30,0.481
21.84,126.10,0.481
21.85,125.90,0.481
21.86,125.70,0.481
21.87,125.50,0.481
21.88,125.30,0.480
21.89,125.10,0.480
21.90,124.90,0.480
21.91,124.70,0.480
21.92,124.50,0.479
21.93,124.30,0.479
21.94,124.10,0.479
21.95,123.90,0.479
21.96,123.70,0.478
21.97,123.50,0.478
21.98,123.30,0.478
21.99,123.10,0.477
22.00,122.90,0.477
22.01,122.70,0.477
22.02,122.50,0.477
22.03,122.30,0.476
22.04,122.10,0.476
22.05,121.90,0.476
22.06,121.70,0.475
22.07,121.50,0.475
22.08,121.30,0.475
22.09,121.10,0.474
22.10,120.90,0.474
22.11,120.70,0.474
22.12,120.51,0.473
22.13,120.30,0.473
22.14,120.11,0.473
22.15,119.91,0.472
22.16,119.71,0.472
22.17,119.51,0.472
22.18,119.31,0.471
22.19,119.11,0.471
22.20,118.91,0.471
22.21,118.71,0.471
22.22,118.51,0.470
22.23,118.31,0.470
22.24,118.11,0.470
22.25,117.91,0.470
22.26,117.71,0.469
22.27,117.51,0.469
22.28,117.31,0.469
22.29,117.11,0.469
22.30,116.91,0.468
22.31,116.71,0.468
22.32,116.51,0.468
22.33,116.31,0.468
22.34,116.11,0.467
22.35,115.91,0.467
22.36,115.71,0.467
22.37,115.51,0.467
22.38,115.31,0.466
22.39,115.11,0.466
22.40,114.91,0.465
22.41,114.71,0.465
22.42,114.51,0.465
22.43,114.31,0.465
22.44,114.11,0.464
22.45,113.92,0.464
22.46,113.72,0.464
22.47,113.52,0.463
22.48,113.32,0.463
22.49,113.12,0.463
22.50,112.92,0.462
22.51,112.72,0.462
22.52,112.52,0.462
22.53,112.32,0.461
22.54,112.12,0.461
22.55,111.92,0.461
22.56,111.72,0.461
22.57,111.52,0.460
22.58,111.32,0.460
22.59,111.12,0.459
22.60,110.92,0.459
22.61,110.72,0.459
22.62,110.52,0.459
22.63,110.32,0.458
22.64,110.12,0.458
22.65,109.92,0.458
22.66,109.72,0.457
22.67,109.52,0.457
22.68,109.32,0.456
22.69,109.12,0.456
22.70,108.92,0.456
22.71,108.72,0.455
22.72,108.52,0.455
22.73,108.32,0.455
22.74,108.13,0.454
22.75,107.92,0.454
22.76,107.73,0.454
22.77,107.53,0.453
22.78,107.33,0.453
22.79,107.13,0.453
22.80,106.93,0.452
22.81,106.73,0.452
22.82,106.53,0.452
22.83,106.33,0.451
22.84,106.13,0.451
22.85,105.93,0.450
22.86,105.73,0.450
22.87,105.53,0.450
22.88,105.33,0.449
22.89,105.13,0.449
22.90,104.93,0.449
22.91,104.73,0.448
22.92,104.53,0.448
22.93,104.33,0.447
22.94,104.13,0.447
22.95,103.93,0.447
22.96,103.73,0.446
22.97,103.53,0.445
22.98,103.33,0.445
22.99,103.13,0.445
23.00,102.93,0.444
23.01,102.73,0.443
23.02,102.53,0.443
23.03,102.33,0.443
23.04,102.13,0.442
23.05,101.94,0.442
23.06,101.74,0.441
23.07,101.53,0.441
23.08,101.34,0.441
23.09,101.14,0.440
23.10,100.94,0.440
23.11,100.74,0.440
23.12,100.54,0.439
23.13,100.34,0.438
23.14,100.14,0.438
23.15,99.94,0.438
23.16,99.74,0.437
23.17,99.54,0.437
23.18,99.34,0.437
23.19,99.14,0.436
23.20,98.94,0.435
23.21,98.74,0.435
23.22,98.54,0.434
23.23,98.34,0.434
23.24,98.14,0.433
23.25,97.94,0.433
23.26,97.74,0.432
23.27,97.54,0.431
23.28,97.34,0.431
23.29,97.14,0.430
23.30,96.94,0.430
23.31,96.74,0.429
23.32,96.54,0.429
23.33,96.34,0.429
23.34,96.14,0.428
23.35,95.95,0.428
23.36,95.75,0.427
23.37,95.55,0.427
23.38,95.35,0.426
23.39,95.15,0.426
23.40,94.95,0.426
23.41,94.75,0.425
23.42,94.55,0.425
23.43,94.35,0.424
23.44,94.15,0.423
23.45,93.95,0.423
23.46,93.75,0.422
23.47,93.55,0.421
23.48,93.35,0.420
23.49,93.15,0.420
23.50,92.95,0.419
23.51,92.75,0.419
23.52,92.55,0.418
23.53,92.35,0.418
23.54,92.15,0.417
23.55,91.95,0.417
23.56,91.75,0.416
23.57,91.55,0.416
23.58,91.35,0.416
23.59,91.15,0.415
23.60,90.95,0.415
23.61,90.75,0.414
23.62,90.55,0.414
23.63,90.36,0.413
23.64,90.16,0.413
23.65,89.96,0.412
23.66,89.76,0.412
23.67,89.56,0.412
23.68,89.36,0.411
23.69,89.16,0.411
23.70,88.96,0.410
23.71,88.76,0.410
23.72,88.56,0.409
23.73,88.36,0.408
23.74,88.16,0.408
23.75,87.96,0.408
23.76,87.76,0.407
23.77,87.56,0.407
23.78,87.36,0.407
23.79,87.16,0.406
23.80,86.96,0.406
23.81,86.76,0.405
23.82,86.56,0.405
23.83,86.36,0.405
23.84,86.16,0.404
23.85,85.96,0.404
23.86,85.76,0.404
23.87,85.56,0.403
23.88,85.36,0.403
23.89,85.16,0.402
23.90,84.97,0.402
23.91,84.76,0.401
23.92,84.57,0.400
23.93,84.37,0.400
23.94,84.17,0.400
23.95,83.97,0.399
23.96,83.77,0.399
23.97,83.57,0.398
23.98,83.37,0.398
23.99,83.17,0.398
24.00,82.97,0.397
24.01,82.77,0.397
24.02,82.57,0.397
24.03,82.37,0.396
24.04,82.17,0.396
24.05,81.97,0.396
24.06,81.77,0.395
24.07,81.57,0.395
24.08,81.37,0.395
24.09,81.17,0.395
24.10,80.97,0.394
24.11,80.77,0.394
24.12,80.57,0.394
24.13,80.37,0.394
24.14,80.18,0.393
24.15,79.98,0.393
24.16,79.78,0.393
24.17,79.58,0.392
24.18,79.38,0.392
24.19,79.18,0.392
24.20,78.98,0.391
24.21,78.78,0.391
24.22,78.58,0.391
24.23,78.38,0.391
24.24,78.18,0.390
24.25,77.98,0.390
24.26,77.78,0.390
24.27,77.58,0.390
24.28,77.38,0.389
24.29,77.18,0.389
24.30,76.98,0.389
24.31,76.78,0.388
24.32,76.58,0.388
24.33,76.38,0.388
24.34,76.19,0.388
24.35,75.99,0.387
24.36,75.79,0.387
24.37,75.59,0.387
24.38,75.39,0.387
24.39,75.19,0.386
24.40,74.99,0.386
24.41,74.79,0.386
24.42,74.59,0.385
24.43,74.39,0.385
24.44,74.19,0.385
24.45,73.99,0.385
24.46,73.79,0.384
24.47,73.59,0.384
24.48,73.39,0.384
24.49,73.19,0.384
24.50,72.99,0.383
24.51,72.79,0.383
24.52,72.59,0.383
24.53,72.39,0.383
24.54,72.19,0.382
24.55,72.00,0.382
24.56,71.80,0.382
24.57,71.60,0.381
24.58,71.40,0.381
24.59,71.20,0.381
24.60,71.00,0.381
24.61,70.80,0.380
24.62,70.60,0.380
24.63,70.40,0.380
24.64,70.20,0.379
24.65,70.00,0.379
24.66,69.80,0.379
24.67,69.60,0.378
24.68,69.40,0.378
24.69,69.20,0.378
24.70,69.00,0.378
24.71,68.80,0.377
24.72,68.60,0.377
24.73,68.40,0.377
24.74,68.20,0.377
24.75,68.01,0.376
24.76,67.81,0.376
24.77,67.61,0.376
24.78,67.41,0.376
24.79,67.21,0.375
24.80,67.01,0.375
24.81,66.81,0.375
24.82,66.61,0.374
24.83,66.41,0.374
24.84,66.21,0.373
24.85,66.01,0.373
24.86,65.81,0.373
24.87,65.61,0.373
24.88,65.41,0.372
24.89,65.22,0.372
24.90,65.02,0.372
24.91,64.82,0.371
24.92,64.62,0.371
24.93,64.42,0.371
24.94,64.22,0.370
24.95,64.02,0.370
24.96,63.82,0.370
24.97,63.62,0.369
24.98,63.42,0.369
24.99,63.22,0.369
25.00,63.02,0.368
25.01,62.82,0.368
25.02,62.62,0.368
25.03,62.42,0.368
25.04,62.22,0.364
25.05,62.02,0.362
25.06,61.82,0.362
25.07,61.63,0.362
25.08,61.43,0.362
25.09,61.23,0.362
25.10,61.03,0.362
25.11,60.83,0.362
25.12,60.63,0.362
25.13,60.43,0.361
25.14,60.23,0.361
25.15,60.03,0.361
25.16,59.83,0.361
25.17,59.63,0.361
25.18,59.43,0.361
25.19,59.23,0.361
25.20,59.03,0.361
25.21,58.83,0.361
25.22,58.63,0.361
25.23,58.43,0.361
25.24,58.23,0.361
25.25,58.03,0.361
25.26,57.83,0.361
25.27,57.63,0.360
25.28,57.43,0.360
25.29,57.23,0.360
25.30,57.03,0.360
25.31,56.83,0.360
25.32,56.63,0.360
25.33,56.43,0.360
25.34,56.23,0.360
25.35,56.03,0.359
25.36,55.83,0.359
25.37,55.63,0.359
25.38,55.43,0.359
25.39,55.23,0.359
25.40,55.03,0.359
25.41,54.83,0.358
25.42,54.63,0.358
25.43,54.43,0.358
25.44,54.23,0.358
25.45,54.03,0.358
25.46,53.83,0.358
25.47,53.63,0.357
25.48,53.43,0.357
25.49,53.23,0.357
25.50,53.03,0.357
25.51,52.83,0.356
25.52,52.63,0.356
25.53,52.43,0.356
25.54,52.23,0.356
25.55,52.03,0.356
25.56,51.83,0.355
25.57,51.63,0.355
25.58,51.43,0.355
25.59,51.23,0.355
25.60,51.03,0.354
25.61,50.83,0.354
25.62,50.63,0.354
25.63,50.43,0.354
25.64,50.23,0.354
25.65,50.03,0.353
25.66,49.83,0.353
25.67,49.64,0.353
25.68,49.43,0.353
25.69,49.23,0.353
25.70,49.03,0.352
25.71,48.83,0.352
25.72,48.63,0.352
25.73,48.43,0.352
25.74,48.23,0.352
25.75,48.03,0.351
25.76,47.83,0.351
25.77,47.63,0.351
25.78,47.43,0.351
25.79,47.23,0.350
25.80,47.03,0.350
25.81,46.83,0.350
25.82,46.63,0.350
25.83,46.43,0.349
25.84,46.23,0.349
25.85,46.03,0.349
25.86,45.83,0.349
25.87,45.63,0.349
25.88,45.43,0.348
25.89,45.23,0.348
25.90,45.03,0.348
25.91,44.83,0.348
25.92,44.63,0.347
25.93,44.43,0.347
25.94,44.23,0.347
25.95,44.03,
25.96,43.83,
25.97,43.63,
25.98,43.43,
25.99,43.23,
26.00,,