File: lab_data_arola_UW/PPS Data/PPS_DSC/pps_unaged_611.txt
Filename	pps_unaged_611
Instrument name	DSC2A-01586 (192.168.10.2)
Operator	Carly Travis
rundate	7/27/2021
Sample name	PPS_Unaged_611
proceduresegments	Ramp 10.00 °C/min to 70.00 °C; Isothermal 1.0 min; Ramp 10.00 °C/min to 300.00 °C; Ramp 10.00 °C/min to 40.00 °C; Mark End of Cycle
[File Parameters]
Run date	7/27/2021 1:42:09 PM
Trios version	5.1.1.46572
Original File Name	C:\ProgramData\TA Instruments\TRIOS\Data\Arola Lab\PPS_Unaged_611.tri
Current File Name	c:\programdata\ta instruments\trios\data\arola lab\pps_unaged_611.tri
[Procedure]
Procedure Name	pps
Sample Name	PPS_Unaged_611
Sample Mass	4.2 mg
Reference Sample Mass	0 mg
Pan Mass	53.4 mg
Pan Number	23
Reference Pan Mass	53.4 mg
Reference Pan Number	1
Pan Type	Aluminum
Comments
Project Name
Operator	Carly Travis
Test	Custom
Unload Max Temperature	40
Unload Min Temperature	40
Load Max Temperature	40
Load Min Temperature	40
Stop on Gas Flow Error	Yes
[Signal List]
Signal #1	Time (min)
Signal #2	Temperature (°C)
Signal #3	Heat Flow (mW)
Signal #4	Delta T (µV)
Signal #5	Delta Tzero (µV)
Signal #6	Tzero Temperature (°C)
Signal #7	Cell Purge (mL/min)
Signal #8	Heater Temp (°C)
Signal #9	Power Delivered (W)
Signal #10	Reference Junction Temperature (°C)
Signal #11	Flange Temperature (°C)
Signal #12	Heat Flow Phase (rad)
Signal #13	Total Heat Capacity (J/°C)
Signal #14	Heat Capacity (J/°C)
[Configuration]
Company Name	UW
Instrument Name	DSC2A-01586
Instrument Type	DSC2500
Serial Number	DSC2A-01586
IP	192.168.10.2
Location of Instrument	UW Bagley 83
DisplayType	TianmaV2
Sample Interval 	0.1 s/pt
Selected Heat Flow	T4P
Exotherm Direction	Up
Cell Serial	DRC2-03254
Lid Type	High Temperature
Cooler	RCS 90
Leave Cooler on at End of Sequence	Off
Gas 2	Nitrogen
Gas Selected	Channel 1
Flow Rate	50 mL/min
Secondary Purge	Off
Licensed Heat Flow	Heat Flow T4P
Modulation Licensed	Yes
[Versions]
Common IDD Version	1
Cortex Version	VER 2.10.2.31
Driver	5.0.0.6
GDM Version	1.0.3.3
TouchscreenVersion	1.0.0.16145
FEP Version	1.2.1.21
FEP Bootloader	2.0.0.5
AutoSampler Version	2.1.1.26
Auto Sampler Bootloader	2.0.0.5
FCM Version	1.1.0.3
FCM Bootloader	2.0.0.5
[Experiment Logs]
Experiment Log Entry # 1	Ramp Segment 10 C/min to 70 Started
Experiment Log Entry # 3	Air Cool is off.
Experiment Log Entry # 5	Isothermal Segment 1 min started
Experiment Log Entry # 7	Ramp Segment 10 C/min to 300 Started
Experiment Log Entry # 9	Ramp Segment 10 C/min to 40 Started
Experiment Log Entry # 11	Mark Data set
[Method Log]
Method Log Entry # 1	(Ramp 335647) Ramp 10 °C/minute to 70 °C
Method Log Entry # 2	Isothermal 1 minutes
Method Log Entry # 3	(Ramp 335649) Ramp 10 °C/minute to 300 °C
Method Log Entry # 4	(Ramp 335650) Ramp 10 °C/minute to 40 °C
Method Log Entry # 5	Mark End 335651
Cell Serial	DRC2-03254
[T1 Calibration]
Date Applied	11/4/2020 3:37:40 PM
Slope	-0.0005345262
Offset	-9.566325
Initial Temperature	-40.80371
GUID	dc124dba-dc9a-4fde-8ac5-9ad7a93db68c
[TZero Calibration]
Date Applied	11/4/2020 11:48:17 PM
Description	From -90.213 °C to 395.512 °C at 20.000°C/min
Gas Type	Nitrogen
Pan Type	None
Source Files 1	C:\ProgramData\TA Instruments\TRIOS\Data\TA SERVICE\DSC2A-01586\Recalibration 04NOV2020 2\Tzero Baseline 110420.tri
Source Files 2	C:\ProgramData\TA Instruments\TRIOS\Data\TA SERVICE\DSC2A-01586\Recalibration 04NOV2020 2\Tzero Sapphire 110420.tri
Delta T Offset	-9.068947
Delta T Slope	-0.0005966381
Delta T0 Offset	4.937698
Delta T0 Slope	0.01193379
[Temperature Calibration]
Date Applied	11/5/2020 1:08:46 AM
Description	From 106.590 °C to 186.590 °C at 10.000°C/min
Gas Type	Nitrogen
Pan Type	Tzero Aluminum
Source Files 1	C:\ProgramData\TA Instruments\TRIOS\Data\TA SERVICE\DSC2A-01586\Recalibration 04NOV2020 2\Indium 110420.tri
Measured 1	157.6191
Known 1	156.598
[Cell Constant Calibration]
Date Applied	11/5/2020 1:08:46 AM
Description	From 106.590 °C to 186.590 °C at 10.000°C/min
Gas Type	Nitrogen
Pan Type	Tzero Aluminum
Source Files 1	C:\ProgramData\TA Instruments\TRIOS\Data\TA SERVICE\DSC2A-01586\Recalibration 04NOV2020 2\Indium 110420.tri
T4P KCell	1.073014
Onset Slope	-60.30231 mW/°C
[Direct Cp Calibration]
(Not Applied)
[Rev Cp Calibration]
(Not Applied)
[step]
Ramp 10.00 °C/min to 70.00 °C
Time	Temperature	Heat Flow (Normalized)
min	°C	W/g
0.00
0.00
0.01
0.01	39.43
0.01	39.44
0.02	39.46
0.02	39.47
0.02	39.48
0.03	39.49
0.03	39.50
0.03	39.51
0.04	39.52
0.04	39.53
0.04	39.54
0.05	39.55
0.05	39.56
0.05	39.57
0.06	39.59
0.06	39.60	-0.801
0.06	39.61	-0.801
0.07	39.63	-0.801
0.07	39.64	-0.801
0.07	39.65	-0.802
0.08	39.67	-0.812
0.08	39.69	-0.829
0.08	39.71	-0.842
0.09	39.72	-0.857
0.09	39.74	-0.873
0.09	39.76	-0.890
0.10	39.78	-0.908
0.10	39.80	-0.926
0.10	39.83	-0.945
0.11	39.85	-0.963
0.11	39.87	-0.981
0.11	39.90	-0.999
0.12	39.92	-1.017
0.12	39.94	-1.034
0.12	39.97	-1.051
0.13	40.00	-1.067
0.13	40.02	-1.082
0.13	40.05	-1.096
0.14	40.07	-1.108
0.14	40.10	-1.121
0.14	40.13	-1.133
0.15	40.16	-1.143
0.15	40.18	-1.153
0.15	40.21	-1.163
0.16	40.24	-1.173
0.16	40.27	-1.182
0.16	40.30	-1.190
0.17	40.32	-1.198
0.17	40.35	-1.205
0.17	40.38	-1.213
0.18	40.41	-1.220
0.18	40.44	-1.227
0.18	40.47	-1.233
0.19	40.50	-1.240
0.19	40.53	-1.247
0.19	40.56	-1.253
0.20	40.59	-1.260
0.20	40.62	-1.265
0.20	40.65	-1.271
0.21	40.68	-1.277
0.21	40.71	-1.283
0.21	40.74	-1.289
0.22	40.77	-1.294
0.22	40.80	-1.299
0.22	40.83	-1.304
0.23	40.87	-1.309
0.23	40.90	-1.315
0.23	40.93	-1.319
0.24	40.96	-1.323
0.24	40.99	-1.328
0.24	41.02	-1.332
0.25	41.06	-1.336
0.25	41.09	-1.339
0.25	41.12	-1.343
0.26	41.15	-1.346
0.26	41.18	-1.348
0.26	41.22	-1.350
0.27	41.25	-1.354
0.27	41.28	-1.357
0.27	41.31	-1.360
0.28	41.35	-1.363
0.28	41.38	-1.364
0.28	41.41	-1.366
0.29	41.44	-1.368
0.29	41.48	-1.369
0.29	41.51	-1.371
0.30	41.54	-1.373
0.30	41.57	-1.375
0.30	41.61	-1.375
0.31	41.64	-1.376
0.31	41.67	-1.377
0.31	41.71	-1.380
0.32	41.74	-1.381
0.32	41.77	-1.383
0.32	41.80	-1.384
0.33	41.84	-1.385
0.33	41.87	-1.386
0.33	41.90	-1.386
0.34	41.94	-1.386
0.34	41.97	-1.386
0.34	42.00	-1.387
0.35	42.04	-1.388
0.35	42.07	-1.389
0.35	42.10	-1.390
0.36	42.14	-1.390
0.36	42.17	-1.391
0.36	42.20	-1.391
0.37	42.24	-1.392
0.37	42.27	-1.392
0.37	42.30	-1.393
0.38	42.33	-1.393
0.38	42.37	-1.393
0.38	42.40	-1.394
0.39	42.44	-1.394
0.39	42.47	-1.395
0.39	42.50	-1.395
0.40	42.54	-1.395
0.40	42.57	-1.395
0.40	42.60	-1.395
0.41	42.64	-1.395
0.41	42.67	-1.395
0.41	42.70	-1.395
0.42	42.74	-1.395
0.42	42.77	-1.395
0.42	42.80	-1.395
0.43	42.84	-1.395
0.43	42.87	-1.395
0.43	42.90	-1.396
0.44	42.94	-1.395
0.44	42.97	-1.395
0.44	43.00	-1.395
0.45	43.04	-1.395
0.45	43.07	-1.395
0.45	43.10	-1.395
0.46	43.14	-1.395
0.46	43.17	-1.395
0.46	43.20	-1.395
0.47	43.24	-1.395
0.47	43.27	-1.395
0.47	43.30	-1.395
0.48	43.34	-1.395
0.48	43.37	-1.395
0.48	43.40	-1.395
0.49	43.44	-1.395
0.49	43.47	-1.395
0.49	43.50	-1.395
0.50	43.54	-1.395
0.50	43.57	-1.395
0.50	43.60	-1.395
0.51	43.64	-1.395
0.51	43.67	-1.395
0.51	43.70	-1.395
0.52	43.74	-1.395
0.52	43.77	-1.394
0.52	43.80	-1.394
0.53	43.84	-1.394
0.53	43.87	-1.394
0.53	43.90	-1.394
0.54	43.94	-1.394
0.54	43.97	-1.394
0.54	44.00	-1.394
0.55	44.04	-1.394
0.55	44.07	-1.394
0.55	44.10	-1.394
0.56	44.14	-1.394
0.56	44.17	-1.394
0.56	44.21	-1.394
0.57	44.24	-1.394
0.57	44.27	-1.394
0.57	44.31	-1.394
0.58	44.34	-1.394
0.58	44.37	-1.394
0.58	44.41	-1.394
0.59	44.44	-1.394
0.59	44.47	-1.394
0.59	44.51	-1.393
0.60	44.54	-1.393
0.60	44.57	-1.393
0.60	44.61	-1.393
0.61	44.64	-1.393
0.61	44.67	-1.393
0.61	44.71	-1.393
0.62	44.74	-1.393
0.62	44.77	-1.393
0.62	44.81	-1.393
0.63	44.84	-1.393
0.63	44.87	-1.393
0.63	44.91	-1.393
0.64	44.94	-1.393
0.64	44.97	-1.393
0.64	45.01	-1.393
0.65	45.04	-1.392
0.65	45.07	-1.392
0.65	45.11	-1.392
0.66	45.14	-1.392
0.66	45.17	-1.392
0.66	45.21	-1.392
0.67	45.24	-1.392
0.67	45.27	-1.392
0.67	45.31	-1.392
0.68	45.34	-1.392
0.68	45.37	-1.392
0.68	45.41	-1.392
0.69	45.44	-1.392
0.69	45.47	-1.392
0.69	45.50	-1.392
0.70	45.54	-1.391
0.70	45.57	-1.391
0.70	45.61	-1.391
0.71	45.64	-1.391
0.71	45.67	-1.391
0.71	45.71	-1.391
0.72	45.74	-1.391
0.72	45.77	-1.391
0.72	45.80	-1.391
0.73	45.84	-1.391
0.73	45.87	-1.391
0.73	45.91	-1.391
0.74	45.94	-1.391
0.74	45.97	-1.391
0.74	46.01	-1.391
0.75	46.04	-1.391
0.75	46.07	-1.391
0.75	46.10	-1.390
0.76	46.14	-1.390
0.76	46.17	-1.390
0.76	46.21	-1.390
0.77	46.24	-1.390
0.77	46.27	-1.390
0.77	46.30	-1.390
0.78	46.34	-1.390
0.78	46.37	-1.390
0.78	46.40	-1.390
0.79	46.44	-1.390
0.79	46.47	-1.390
0.79	46.50	-1.390
0.80	46.54	-1.390
0.80	46.57	-1.390
0.80	46.60	-1.390
0.81	46.64	-1.390
0.81	46.67	-1.390
0.81	46.71	-1.390
0.82	46.74	-1.390
0.82	46.77	-1.389
0.82	46.81	-1.389
0.83	46.84	-1.389
0.83	46.87	-1.389
0.83	46.91	-1.389
0.84	46.94	-1.389
0.84	46.97	-1.389
0.84	47.01	-1.389
0.85	47.04	-1.389
0.85	47.07	-1.389
0.85	47.11	-1.389
0.86	47.14	-1.389
0.86	47.17	-1.389
0.86	47.21	-1.389
0.87	47.24	-1.389
0.87	47.27	-1.389
0.87	47.30	-1.389
0.88	47.34	-1.389
0.88	47.37	-1.389
0.88	47.40	-1.389
0.89	47.44	-1.389
0.89	47.47	-1.389
0.89	47.50	-1.389
0.90	47.54	-1.388
0.90	47.57	-1.388
0.90	47.60	-1.388
0.91	47.64	-1.388
0.91	47.67	-1.388
0.91	47.70	-1.388
0.92	47.74	-1.388
0.92	47.77	-1.388
0.92	47.80	-1.388
0.93	47.84	-1.388
0.93	47.87	-1.388
0.93	47.90	-1.388
0.94	47.94	-1.388
0.94	47.97	-1.388
0.94	48.00	-1.388
0.95	48.04	-1.388
0.95	48.07	-1.388
0.95	48.10	-1.388
0.96	48.14	-1.388
0.96	48.17	-1.388
0.96	48.20	-1.388
0.97	48.24	-1.388
0.97	48.27	-1.388
0.97	48.30	-1.388
0.98	48.34	-1.388
0.98	48.37	-1.388
0.98	48.40	-1.388
0.99	48.44	-1.388
0.99	48.47	-1.388
0.99	48.50	-1.388
1.00	48.54	-1.388
1.00	48.57	-1.388
1.00	48.60	-1.388
1.01	48.64	-1.388
1.01	48.67	-1.388
1.01	48.70	-1.388
1.02	48.74	-1.388
1.02	48.77	-1.388
1.02	48.80	-1.388
1.03	48.84	-1.388
1.03	48.87	-1.388
1.03	48.90	-1.388
1.04	48.94	-1.388
1.04	48.97	-1.388
1.04	49.00	-1.388
1.05	49.04	-1.388
1.05	49.07	-1.388
1.05	49.10	-1.388
1.06	49.14	-1.388
1.06	49.17	-1.388
1.06	49.20	-1.388
1.07	49.24	-1.388
1.07	49.27	-1.388
1.07	49.30	-1.388
1.08	49.34	-1.388
1.08	49.37	-1.388
1.08	49.40	-1.388
1.09	49.43	-1.388
1.09	49.47	-1.388
1.09	49.50	-1.388
1.10	49.54	-1.388
1.10	49.57	-1.388
1.10	49.60	-1.388
1.11	49.64	-1.388
1.11	49.67	-1.388
1.11	49.70	-1.388
1.12	49.74	-1.389
1.12	49.77	-1.389
1.12	49.80	-1.389
1.13	49.83	-1.389
1.13	49.87	-1.389
1.13	49.90	-1.389
1.14	49.93	-1.389
1.14	49.97	-1.389
1.14	50.00	-1.389
1.15	50.04	-1.389
1.15	50.07	-1.389
1.15	50.10	-1.389
1.16	50.14	-1.389
1.16	50.17	-1.389
1.16	50.20	-1.389
1.17	50.23	-1.389
1.17	50.27	-1.389
1.17	50.30	-1.389
1.18	50.34	-1.389
1.18	50.37	-1.389
1.18	50.40	-1.389
1.19	50.44	-1.389
1.19	50.47	-1.389
1.19	50.50	-1.389
1.20	50.54	-1.389
1.20	50.57	-1.389
1.20	50.60	-1.389
1.21	50.64	-1.389
1.21	50.67	-1.389
1.21	50.70	-1.390
1.22	50.74	-1.390
1.22	50.77	-1.390
1.22	50.80	-1.390
1.23	50.83	-1.390
1.23	50.87	-1.390
1.23	50.90	-1.390
1.24	50.94	-1.390
1.24	50.97	-1.390
1.24	51.00	-1.390
1.25	51.03	-1.390
1.25	51.07	-1.390
1.25	51.10	-1.390
1.26	51.13	-1.390
1.26	51.17	-1.390
1.26	51.20	-1.390
1.27	51.23	-1.390
1.27	51.27	-1.390
1.27	51.30	-1.390
1.28	51.33	-1.390
1.28	51.37	-1.390
1.28	51.40	-1.390
1.29	51.44	-1.390
1.29	51.47	-1.390
1.29	51.50	-1.390
1.30	51.53	-1.391
1.30	51.57	-1.391
1.30	51.60	-1.391
1.31	51.63	-1.391
1.31	51.67	-1.391
1.31	51.70	-1.391
1.32	51.73	-1.391
1.32	51.77	-1.391
1.32	51.80	-1.391
1.33	51.83	-1.391
1.33	51.87	-1.391
1.33	51.90	-1.391
1.34	51.93	-1.391
1.34	51.97	-1.391
1.34	52.00	-1.391
1.35	52.03	-1.391
1.35	52.07	-1.391
1.35	52.10	-1.391
1.36	52.13	-1.391
1.36	52.17	-1.391
1.36	52.20	-1.391
1.37	52.23	-1.391
1.37	52.27	-1.392
1.37	52.30	-1.392
1.38	52.34	-1.392
1.38	52.37	-1.392
1.38	52.40	-1.392
1.39	52.43	-1.392
1.39	52.47	-1.392
1.39	52.50	-1.392
1.40	52.53	-1.392
1.40	52.57	-1.392
1.40	52.60	-1.392
1.41	52.63	-1.392
1.41	52.67	-1.392
1.41	52.70	-1.392
1.42	52.73	-1.392
1.42	52.77	-1.392
1.42	52.80	-1.392
1.43	52.83	-1.392
1.43	52.87	-1.392
1.43	52.90	-1.392
1.44	52.93	-1.393
1.44	52.97	-1.393
1.44	53.00	-1.393
1.45	53.03	-1.393
1.45	53.07	-1.393
1.45	53.10	-1.393
1.46	53.13	-1.393
1.46	53.17	-1.393
1.46	53.20	-1.393
1.47	53.23	-1.393
1.47	53.27	-1.393
1.47	53.30	-1.393
1.48	53.33	-1.393
1.48	53.37	-1.393
1.48	53.40	-1.393
1.49	53.43	-1.393
1.49	53.47	-1.393
1.49	53.50	-1.393
1.50	53.53	-1.394
1.50	53.57	-1.394
1.50	53.60	-1.394
1.51	53.63	-1.394
1.51	53.67	-1.394
1.51	53.70	-1.394
1.52	53.73	-1.394
1.52	53.77	-1.394
1.52	53.80	-1.394
1.53	53.83	-1.394
1.53	53.87	-1.394
1.53	53.90	-1.394
1.54	53.93	-1.394
1.54	53.97	-1.394
1.54	54.00	-1.394
1.55	54.03	-1.394
1.55	54.07	-1.394
1.55	54.10	-1.394
1.56	54.13	-1.394
1.56	54.17	-1.395
1.56	54.20	-1.395
1.57	54.23	-1.395
1.57	54.27	-1.395
1.57	54.30	-1.395
1.58	54.33	-1.395
1.58	54.37	-1.395
1.58	54.40	-1.395
1.59	54.43	-1.395
1.59	54.47	-1.395
1.59	54.50	-1.395
1.60	54.53	-1.395
1.60	54.57	-1.395
1.60	54.60	-1.395
1.61	54.63	-1.395
1.61	54.67	-1.395
1.61	54.70	-1.395
1.62	54.73	-1.395
1.62	54.77	-1.395
1.62	54.80	-1.395
1.63	54.83	-1.396
1.63	54.87	-1.396
1.63	54.90	-1.396
1.64	54.93	-1.396
1.64	54.97	-1.396
1.64	55.00	-1.396
1.65	55.03	-1.396
1.65	55.07	-1.396
1.65	55.10	-1.396
1.66	55.13	-1.396
1.66	55.17	-1.396
1.66	55.20	-1.396
1.67	55.23	-1.396
1.67	55.27	-1.396
1.67	55.30	-1.396
1.68	55.33	-1.396
1.68	55.37	-1.396
1.68	55.40	-1.396
1.69	55.43	-1.396
1.69	55.47	-1.396
1.69	55.50	-1.397
1.70	55.53	-1.397
1.70	55.57	-1.397
1.70	55.60	-1.397
1.71	55.63	-1.397
1.71	55.67	-1.397
1.71	55.70	-1.397
1.72	55.73	-1.397
1.72	55.77	-1.397
1.72	55.80	-1.397
1.73	55.83	-1.397
1.73	55.87	-1.397
1.73	55.90	-1.397
1.74	55.93	-1.397
1.74	55.97	-1.397
1.74	56.00	-1.397
1.75	56.04	-1.397
1.75	56.07	-1.397
1.75	56.10	-1.397
1.76	56.13	-1.397
1.76	56.17	-1.398
1.76	56.20	-1.398
1.77	56.23	-1.398
1.77	56.27	-1.398
1.77	56.30	-1.398
1.78	56.33	-1.398
1.78	56.37	-1.398
1.78	56.40	-1.398
1.79	56.43	-1.398
1.79	56.47	-1.398
1.79	56.50	-1.398
1.80	56.53	-1.398
1.80	56.57	-1.398
1.80	56.60	-1.398
1.81	56.63	-1.398
1.81	56.67	-1.398
1.81	56.70	-1.398
1.82	56.73	-1.398
1.82	56.77	-1.398
1.82	56.80	-1.398
1.83	56.83	-1.399
1.83	56.87	-1.399
1.83	56.90	-1.399
1.84	56.93	-1.399
1.84	56.97	-1.399
1.84	57.00	-1.399
1.85	57.03	-1.399
1.85	57.07	-1.399
1.85	57.10	-1.399
1.86	57.14	-1.399
1.86	57.17	-1.399
1.86	57.20	-1.399
1.87	57.24	-1.399
1.87	57.27	-1.399
1.87	57.30	-1.399
1.88	57.33	-1.399
1.88	57.37	-1.399
1.88	57.40	-1.400
1.89	57.43	-1.400
1.89	57.47	-1.400
1.89	57.50	-1.400
1.90	57.53	-1.400
1.90	57.57	-1.400
1.90	57.60	-1.400
1.91	57.63	-1.400
1.91	57.67	-1.400
1.91	57.70	-1.400
1.92	57.73	-1.400
1.92	57.77	-1.400
1.92	57.80	-1.400
1.93	57.83	-1.400
1.93	57.87	-1.400
1.93	57.90	-1.400
1.94	57.93	-1.400
1.94	57.97	-1.400
1.94	58.00	-1.401
1.95	58.04	-1.401
1.95	58.07	-1.401
1.95	58.10	-1.401
1.96	58.13	-1.401
1.96	58.17	-1.401
1.96	58.20	-1.401
1.97	58.24	-1.401
1.97	58.27	-1.401
1.97	58.30	-1.401
1.98	58.33	-1.401
1.98	58.37	-1.401
1.98	58.40	-1.401
1.99	58.44	-1.401
1.99	58.47	-1.401
1.99	58.50	-1.401
2.00	58.54	-1.401
2.00	58.57	-1.402
2.00	58.60	-1.402
2.01	58.63	-1.402
2.01	58.67	-1.402
2.01	58.70	-1.402
2.02	58.73	-1.402
2.02	58.77	-1.402
2.02	58.80	-1.402
2.03	58.83	-1.402
2.03	58.87	-1.402
2.03	58.90	-1.402
2.04	58.94	-1.402
2.04	58.97	-1.402
2.04	59.00	-1.402
2.05	59.04	-1.402
2.05	59.07	-1.402
2.05	59.10	-1.402
2.06	59.13	-1.402
2.06	59.17	-1.403
2.06	59.20	-1.403
2.07	59.23	-1.403
2.07	59.27	-1.403
2.07	59.30	-1.403
2.08	59.34	-1.403
2.08	59.37	-1.403
2.08	59.40	-1.403
2.09	59.43	-1.403
2.09	59.47	-1.403
2.09	59.50	-1.403
2.10	59.53	-1.403
2.10	59.57	-1.403
2.10	59.60	-1.403
2.11	59.63	-1.403
2.11	59.67	-1.403
2.11	59.70	-1.404
2.12	59.73	-1.404
2.12	59.77	-1.404
2.12	59.80	-1.404
2.13	59.84	-1.404
2.13	59.87	-1.404
2.13	59.90	-1.404
2.14	59.94	-1.404
2.14	59.97	-1.404
2.14	60.00	-1.404
2.15	60.04	-1.404
2.15	60.07	-1.404
2.15	60.10	-1.404
2.16	60.14	-1.404
2.16	60.17	-1.405
2.16	60.20	-1.405
2.17	60.24	-1.405
2.17	60.27	-1.405
2.17	60.30	-1.405
2.18	60.33	-1.405
2.18	60.37	-1.405
2.18	60.40	-1.405
2.19	60.44	-1.405
2.19	60.47	-1.405
2.19	60.50	-1.405
2.20	60.54	-1.405
2.20	60.57	-1.405
2.20	60.60	-1.405
2.21	60.64	-1.405
2.21	60.67	-1.406
2.21	60.70	-1.406
2.22	60.74	-1.406
2.22	60.77	-1.406
2.22	60.80	-1.406
2.23	60.84	-1.406
2.23	60.87	-1.406
2.23	60.90	-1.406
2.24	60.94	-1.406
2.24	60.97	-1.406
2.24	61.00	-1.406
2.25	61.03	-1.406
2.25	61.07	-1.406
2.25	61.10	-1.406
2.26	61.14	-1.406
2.26	61.17	-1.406
2.26	61.20	-1.406
2.27	61.24	-1.407
2.27	61.27	-1.407
2.27	61.30	-1.407
2.28	61.34	-1.407
2.28	61.37	-1.407
2.28	61.40	-1.407
2.29	61.44	-1.407
2.29	61.47	-1.407
2.29	61.50	-1.407
2.30	61.53	-1.407
2.30	61.57	-1.407
2.30	61.60	-1.407
2.31	61.64	-1.407
2.31	61.67	-1.407
2.31	61.70	-1.407
2.32	61.74	-1.407
2.32	61.77	-1.408
2.32	61.80	-1.408
2.33	61.84	-1.408
2.33	61.87	-1.408
2.33	61.90	-1.408
2.34	61.94	-1.408
2.34	61.97	-1.408
2.34	62.00	-1.408
2.35	62.04	-1.408
2.35	62.07	-1.408
2.35	62.10	-1.408
2.36	62.14	-1.408
2.36	62.17	-1.408
2.36	62.20	-1.408
2.37	62.24	-1.408
2.37	62.27	-1.409
2.37	62.30	-1.409
2.38	62.34	-1.409
2.38	62.37	-1.409
2.38	62.40	-1.409
2.39	62.44	-1.409
2.39	62.47	-1.409
2.39	62.50	-1.409
2.40	62.54	-1.409
2.40	62.57	-1.409
2.40	62.60	-1.409
2.41	62.64	-1.409
2.41	62.67	-1.409
2.41	62.70	-1.409
2.42	62.74	-1.409
2.42	62.77	-1.410
2.42	62.80	-1.410
2.43	62.84	-1.410
2.43	62.87	-1.410
2.43	62.90	-1.410
2.44	62.94	-1.410
2.44	62.97	-1.410
2.44	63.00	-1.410
2.45	63.04	-1.410
2.45	63.07	-1.410
2.45	63.10	-1.410
2.46	63.14	-1.410
2.46	63.17	-1.410
2.46	63.20	-1.410
2.47	63.24	-1.411
2.47	63.27	-1.411
2.47	63.30	-1.411
2.48	63.34	-1.411
2.48	63.37	-1.411
2.48	63.40	-1.411
2.49	63.44	-1.411
2.49	63.47	-1.411
2.49	63.50	-1.411
2.50	63.54	-1.411
2.50	63.57	-1.411
2.50	63.60	-1.411
2.51	63.64	-1.411
2.51	63.67	-1.411
2.51	63.70	-1.412
2.52	63.74	-1.412
2.52	63.77	-1.412
2.52	63.80	-1.412
2.53	63.84	-1.412
2.53	63.87	-1.412
2.53	63.90	-1.412
2.54	63.94	-1.412
2.54	63.97	-1.412
2.54	64.00	-1.412
2.55	64.04	-1.412
2.55	64.07	-1.412
2.55	64.10	-1.412
2.56	64.14	-1.413
2.56	64.17	-1.413
2.56	64.20	-1.413
2.57	64.24	-1.413
2.57	64.27	-1.413
2.57	64.30	-1.413
2.58	64.34	-1.413
2.58	64.37	-1.413
2.58	64.40	-1.413
2.59	64.44	-1.413
2.59	64.47	-1.413
2.59	64.50	-1.413
2.60	64.54	-1.413
2.60	64.57	-1.413
2.60	64.60	-1.413
2.61	64.64	-1.413
2.61	64.67	-1.413
2.61	64.70	-1.414
2.62	64.74	-1.414
2.62	64.77	-1.414
2.62	64.80	-1.414
2.63	64.84	-1.414
2.63	64.87	-1.414
2.63	64.90	-1.414
2.64	64.94	-1.414
2.64	64.97	-1.414
2.64	65.01	-1.414
2.65	65.04	-1.414
2.65	65.07	-1.414
2.65	65.10	-1.414
2.66	65.14	-1.414
2.66	65.17	-1.414
2.66	65.20	-1.414
2.67	65.24	-1.414
2.67	65.27	-1.414
2.67	65.30	-1.415
2.68	65.34	-1.415
2.68	65.37	-1.415
2.68	65.41	-1.415
2.69	65.44	-1.415
2.69	65.47	-1.415
2.69	65.50	-1.415
2.70	65.54	-1.415
2.70	65.57	-1.415
2.70	65.61	-1.415
2.71	65.64	-1.415
2.71	65.67	-1.415
2.71	65.70	-1.415
2.72	65.74	-1.415
2.72	65.77	-1.415
2.72	65.81	-1.415
2.73	65.84	-1.415
2.73	65.87	-1.416
2.73	65.91	-1.416
2.74	65.94	-1.416
2.74	65.97	-1.416
2.74	66.00	-1.416
2.75	66.04	-1.416
2.75	66.07	-1.416
2.75	66.10	-1.416
2.76	66.14	-1.416
2.76	66.17	-1.416
2.76	66.20	-1.416
2.77	66.24	-1.416
2.77	66.27	-1.416
2.77	66.31	-1.416
2.78	66.34	-1.417
2.78	66.37	-1.417
2.78	66.40	-1.417
2.79	66.44	-1.417
2.79	66.47	-1.417
2.79	66.51	-1.417
2.80	66.54	-1.417
2.80	66.57	-1.417
2.80	66.61	-1.417
2.81	66.64	-1.417
2.81	66.67	-1.417
2.81	66.71	-1.417
2.82	66.74	-1.418
2.82	66.77	-1.418
2.82	66.81	-1.418
2.83	66.84	-1.418
2.83	66.87	-1.418
2.83	66.91	-1.418
2.84	66.94	-1.418
2.84	66.97	-1.418
2.84	67.01	-1.418
2.85	67.04	-1.418
2.85	67.07	-1.418
2.85	67.10	-1.418
2.86	67.14	-1.418
2.86	67.17	-1.418
2.86	67.21	-1.418
2.87	67.24	-1.419
2.87	67.27	-1.419
2.87	67.31	-1.419
2.88	67.34	-1.419
2.88	67.37	-1.419
2.88	67.41	-1.419
2.89	67.44	-1.419
2.89	67.47	-1.419
2.89	67.51	-1.419
2.90	67.54	-1.419
2.90	67.57	-1.419
2.90	67.61	-1.419
2.91	67.64	-1.419
2.91	67.67	-1.419
2.91	67.71	-1.419
2.92	67.74	-1.419
2.92	67.77	-1.419
2.92	67.81	-1.419
2.93	67.84	-1.420
2.93	67.87	-1.420
2.93	67.91	-1.420
2.94	67.94	-1.420
2.94	67.97	-1.420
2.94	68.01	-1.420
2.95	68.04	-1.420
2.95	68.07	-1.420
2.95	68.11	-1.420
2.96	68.14	-1.420
2.96	68.17	-1.420
2.96	68.21	-1.420
2.97	68.24	-1.420
2.97	68.27	-1.420
2.97	68.31	-1.420
2.98	68.34	-1.420
2.98	68.37	-1.421
2.98	68.41	-1.421
2.99	68.44	-1.421
2.99	68.47	-1.421
2.99	68.51	-1.421
3.00	68.54	-1.421
3.00	68.57	-1.421

[step]
Isothermal 1.0 min
Time	Temperature	Heat Flow (Normalized)
min	°C	W/g
3.00	68.59	-1.421
3.00	68.61	-1.421
3.01	68.62	-1.421
3.01	68.64	-1.421
3.01	68.66	-1.421
3.01	68.67	-1.421
3.01	68.69	-1.421
3.01	68.71	-1.421
3.01	68.72	-1.421
3.02	68.74	-1.421
3.02	68.76	-1.421
3.02	68.77	-1.421
3.02	68.79	-1.421
3.02	68.81	-1.421
3.03	68.82	-1.421
3.03	68.84	-1.421
3.03	68.85	-1.421
3.03	68.87	-1.421
3.03	68.89	-1.421
3.03	68.90	-1.421
3.04	68.92	-1.421
3.04	68.93	-1.421
3.04	68.95	-1.421
3.04	68.96	-1.421
3.04	68.98	-1.420
3.04	68.99	-1.419
3.04	69.01	-1.417
3.05	69.03	-1.415
3.05	69.04	-1.411
3.05	69.06	-1.406
3.05	69.07	-1.402
3.05	69.09	-1.396
3.06	69.10	-1.392
3.06	69.12	-1.388
3.06	69.13	-1.383
3.06	69.14	-1.378
3.06	69.16	-1.372
3.06	69.17	-1.367
3.06	69.19	-1.359
3.07	69.20	-1.352
3.07	69.21	-1.345
3.07	69.22	-1.338
3.07	69.24	-1.330
3.07	69.25	-1.321
3.08	69.26	-1.313
3.08	69.28	-1.304
3.08	69.29	-1.294
3.08	69.30	-1.285
3.08	69.31	-1.274
3.08	69.32	-1.264
3.09	69.34	-1.253
3.09	69.35	-1.242
3.09	69.36	-1.231
3.09	69.37	-1.219
3.09	69.38	-1.208
3.09	69.39	-1.196
3.09	69.40	-1.183
3.10	69.41	-1.171
3.10	69.42	-1.158
3.10	69.43	-1.145
3.10	69.44	-1.133
3.10	69.45	-1.120
3.11	69.46	-1.107
3.11	69.47	-1.094
3.11	69.48	-1.081
3.11	69.48	-1.068
3.11	69.49	-1.055
3.11	69.50	-1.042
3.11	69.51	-1.029
3.12	69.52	-1.016
3.12	69.52	-1.003
3.12	69.53	-0.990
3.12	69.54	-0.977
3.12	69.55	-0.964
3.13	69.55	-0.951
3.13	69.56	-0.938
3.13	69.57	-0.926
3.13	69.57	-0.913
3.13	69.58	-0.901
3.13	69.59	-0.888
3.14	69.59	-0.876
3.14	69.60	-0.865
3.14	69.60	-0.853
3.14	69.61	-0.841
3.14	69.62	-0.829
3.14	69.62	-0.818
3.14	69.63	-0.807
3.15	69.63	-0.796
3.15	69.64	-0.786
3.15	69.64	-0.775
3.15	69.65	-0.765
3.15	69.65	-0.754
3.16	69.66	-0.744
3.16	69.66	-0.733
3.16	69.67	-0.723
3.16	69.67	-0.713
3.16	69.68	-0.703
3.16	69.68	-0.693
3.16	69.69	-0.684
3.17	69.69	-0.675
3.17	69.70	-0.666
3.17	69.70	-0.657
3.17	69.70	-0.648
3.17	69.71	-0.639
3.18	69.71	-0.630
3.18	69.72	-0.622
3.18	69.72	-0.614
3.18	69.73	-0.606
3.18	69.73	-0.598
3.18	69.74	-0.590
3.19	69.74	-0.581
3.19	69.74	-0.573
3.19	69.75	-0.565
3.19	69.75	-0.558
3.19	69.75	-0.550
3.19	69.76	-0.542
3.19	69.76	-0.536
3.20	69.76	-0.528
3.20	69.77	-0.521
3.20	69.77	-0.514
3.20	69.77	-0.507
3.20	69.78	-0.500
3.21	69.78	-0.493
3.21	69.78	-0.486
3.21	69.79	-0.480
3.21	69.79	-0.473
3.21	69.79	-0.466
3.21	69.79	-0.460
3.21	69.80	-0.454
3.22	69.80	-0.447
3.22	69.80	-0.441
3.22	69.81	-0.435
3.22	69.81	-0.429
3.22	69.81	-0.423
3.23	69.81	-0.417
3.23	69.82	-0.411
3.23	69.82	-0.406
3.23	69.82	-0.400
3.23	69.82	-0.395
3.23	69.83	-0.389
3.24	69.83	-0.383
3.24	69.83	-0.378
3.24	69.83	-0.373
3.24	69.83	-0.367
3.24	69.84	-0.362
3.24	69.84	-0.357
3.24	69.84	-0.352
3.25	69.84	-0.347
3.25	69.85	-0.343
3.25	69.85	-0.338
3.25	69.85	-0.334
3.25	69.85	-0.329
3.26	69.85	-0.324
3.26	69.85	-0.319
3.26	69.86	-0.314
3.26	69.86	-0.310
3.26	69.86	-0.306
3.26	69.86	-0.302
3.26	69.86	-0.298
3.27	69.86	-0.293
3.27	69.87	-0.289
3.27	69.87	-0.285
3.27	69.87	-0.281
3.27	69.87	-0.278
3.28	69.87	-0.273
3.28	69.87	-0.269
3.28	69.88	-0.265
3.28	69.88	-0.262
3.28	69.88	-0.258
3.28	69.88	-0.254
3.29	69.88	-0.251
3.29	69.88	-0.248
3.29	69.88	-0.245
3.29	69.88	-0.242
3.29	69.89	-0.239
3.29	69.89	-0.235
3.29	69.89	-0.232
3.30	69.89	-0.229
3.30	69.89	-0.226
3.30	69.89	-0.223
3.30	69.89	-0.220
3.30	69.89	-0.217
3.31	69.90	-0.214
3.31	69.90	-0.211
3.31	69.90	-0.209
3.31	69.90	-0.206
3.31	69.90	-0.203
3.31	69.90	-0.201
3.31	69.90	-0.198
3.32	69.90	-0.195
3.32	69.91	-0.193
3.32	69.91	-0.190
3.32	69.91	-0.188
3.32	69.91	-0.186
3.33	69.91	-0.184
3.33	69.91	-0.182
3.33	69.91	-0.180
3.33	69.91	-0.177
3.33	69.91	-0.175
3.33	69.91	-0.173
3.34	69.91	-0.171
3.34	69.92	-0.169
3.34	69.92	-0.167
3.34	69.92	-0.165
3.34	69.92	-0.163
3.34	69.92	-0.161
3.34	69.92	-0.159
3.35	69.92	-0.157
3.35	69.92	-0.155
3.35	69.92	-0.153
3.35	69.92	-0.151
3.35	69.92	-0.149
3.36	69.92	-0.148
3.36	69.93	-0.146
3.36	69.93	-0.145
3.36	69.93	-0.143
3.36	69.93	-0.141
3.36	69.93	-0.139
3.36	69.93	-0.138
3.37	69.93	-0.135
3.37	69.93	-0.134
3.37	69.93	-0.132
3.37	69.93	-0.130
3.37	69.93	-0.129
3.38	69.93	-0.127
3.38	69.93	-0.126
3.38	69.93	-0.125
3.38	69.93	-0.123
3.38	69.93	-0.122
3.38	69.93	-0.121
3.39	69.94	-0.119
3.39	69.94	-0.118
3.39	69.94	-0.117
3.39	69.94	-0.115
3.39	69.94	-0.114
3.39	69.94	-0.113
3.39	69.94	-0.111
3.40	69.94	-0.111
3.40	69.94	-0.110
3.40	69.94	-0.109
3.40	69.94	-0.108
3.40	69.94	-0.106
3.41	69.94	-0.105
3.41	69.94	-0.104
3.41	69.94	-0.103
3.41	69.94	-0.102
3.41	69.94	-0.101
3.41	69.94	-0.100
3.41	69.94	-0.099
3.42	69.94	-0.097
3.42	69.94	-0.097
3.42	69.95	-0.096
3.42	69.95	-0.095
3.42	69.95	-0.094
3.43	69.95	-0.093
3.43	69.95	-0.092
3.43	69.95	-0.091
3.43	69.95	-0.090
3.43	69.95	-0.089
3.43	69.95	-0.089
3.44	69.95	-0.089
3.44	69.95	-0.087
3.44	69.95	-0.086
3.44	69.95	-0.085
3.44	69.95	-0.085
3.44	69.95	-0.083
3.44	69.95	-0.083
3.45	69.95	-0.082
3.45	69.95	-0.082
3.45	69.95	-0.081
3.45	69.95	-0.081
3.45	69.95	-0.080
3.46	69.95	-0.080
3.46	69.95	-0.079
3.46	69.95	-0.078
3.46	69.95	-0.077
3.46	69.95	-0.077
3.46	69.95	-0.076
3.46	69.95	-0.076
3.47	69.96	-0.075
3.47	69.96	-0.075
3.47	69.96	-0.074
3.47	69.96	-0.074
3.47	69.96	-0.073
3.48	69.96	-0.073
3.48	69.96	-0.072
3.48	69.96	-0.072
3.48	69.96	-0.071
3.48	69.96	-0.071
3.48	69.96	-0.070
3.49	69.96	-0.070
3.49	69.96	-0.069
3.49	69.96	-0.069
3.49	69.96	-0.068
3.49	69.96	-0.068
3.49	69.96	-0.068
3.49	69.96	-0.067
3.50	69.96	-0.067
3.50	69.96	-0.066
3.50	69.96	-0.066
3.50	69.96	-0.065
3.50	69.96	-0.065
3.51	69.96	-0.064
3.51	69.96	-0.064
3.51	69.96	-0.063
3.51	69.96	-0.063
3.51	69.96	-0.062
3.51	69.96	-0.062
3.51	69.96	-0.062
3.52	69.96	-0.062
3.52	69.96	-0.061
3.52	69.96	-0.061
3.52	69.96	-0.061
3.52	69.96	-0.061
3.53	69.96	-0.060
3.53	69.96	-0.060
3.53	69.96	-0.059
3.53	69.96	-0.059
3.53	69.96	-0.059
3.53	69.96	-0.059
3.54	69.96	-0.058
3.54	69.96	-0.058
3.54	69.96	-0.058
3.54	69.96	-0.058
3.54	69.96	-0.057
3.54	69.96	-0.057
3.54	69.97	-0.057
3.55	69.97	-0.057
3.55	69.97	-0.057
3.55	69.97	-0.056
3.55	69.97	-0.056
3.55	69.97	-0.056
3.56	69.97	-0.056
3.56	69.97	-0.056
3.56	69.97	-0.055
3.56	69.97	-0.055
3.56	69.97	-0.055
3.56	69.97	-0.054
3.56	69.97	-0.054
3.57	69.97	-0.054
3.57	69.97	-0.054
3.57	69.97	-0.054
3.57	69.97	-0.053
3.57	69.97	-0.053
3.58	69.97	-0.053
3.58	69.97	-0.053
3.58	69.97	-0.053
3.58	69.97	-0.052
3.58	69.97	-0.052
3.58	69.97	-0.052
3.59	69.97	-0.052
3.59	69.97	-0.052
3.59	69.97	-0.051
3.59	69.97	-0.051
3.59	69.97	-0.051
3.59	69.97	-0.051
3.59	69.97	-0.050
3.60	69.97	-0.050
3.60	69.97	-0.050
3.60	69.97	-0.050
3.60	69.97	-0.050
3.60	69.97	-0.050
3.61	69.97	-0.050
3.61	69.97	-0.050
3.61	69.97	-0.050
3.61	69.97	-0.049
3.61	69.97	-0.049
3.61	69.97	-0.049
3.61	69.97	-0.049
3.62	69.97	-0.049
3.62	69.97	-0.048
3.62	69.97	-0.048
3.62	69.97	-0.048
3.62	69.97	-0.048
3.63	69.97	-0.048
3.63	69.97	-0.048
3.63	69.97	-0.048
3.63	69.97	-0.048
3.63	69.97	-0.048
3.63	69.97	-0.047
3.64	69.97	-0.047
3.64	69.97	-0.047
3.64	69.97	-0.047
3.64	69.97	-0.047
3.64	69.97	-0.047
3.64	69.97	-0.047
3.64	69.97	-0.047
3.65	69.97	-0.047
3.65	69.97	-0.047
3.65	69.98	-0.047
3.65	69.97	-0.047
3.65	69.97	-0.047
3.66	69.97	-0.047
3.66	69.98	-0.046
3.66	69.98	-0.046
3.66	69.98	-0.046
3.66	69.98	-0.046
3.66	69.98	-0.046
3.66	69.98	-0.046
3.67	69.98	-0.046
3.67	69.98	-0.046
3.67	69.98	-0.046
3.67	69.98	-0.046
3.67	69.98	-0.046
3.68	69.98	-0.046
3.68	69.98	-0.046
3.68	69.98	-0.045
3.68	69.98	-0.045
3.68	69.98	-0.045
3.68	69.98	-0.045
3.69	69.98	-0.045
3.69	69.98	-0.045
3.69	69.98	-0.045
3.69	69.98	-0.045
3.69	69.98	-0.045
3.69	69.98	-0.045
3.69	69.98	-0.045
3.70	69.98	-0.045
3.70	69.98	-0.045
3.70	69.98	-0.045
3.70	69.98	-0.044
3.70	69.98	-0.044
3.71	69.98	-0.044
3.71	69.98	-0.044
3.71	69.98	-0.044
3.71	69.98	-0.044
3.71	69.98	-0.044
3.71	69.98	-0.044
3.71	69.98	-0.044
3.72	69.98	-0.044
3.72	69.98	-0.044
3.72	69.98	-0.044
3.72	69.98	-0.044
3.72	69.98	-0.044
3.73	69.98	-0.043
3.73	69.98	-0.043
3.73	69.98	-0.043
3.73	69.98	-0.043
3.73	69.98	-0.043
3.73	69.98	-0.043
3.74	69.98	-0.043
3.74	69.98	-0.043
3.74	69.98	-0.043
3.74	69.98	-0.043
3.74	69.98	-0.043
3.74	69.98	-0.043
3.74	69.98	-0.043
3.75	69.98	-0.043
3.75	69.98	-0.042
3.75	69.98	-0.042
3.75	69.98	-0.042
3.75	69.98	-0.042
3.76	69.98	-0.042
3.76	69.98	-0.042
3.76	69.98	-0.042
3.76	69.98	-0.042
3.76	69.98	-0.042
3.76	69.98	-0.042
3.76	69.98	-0.042
3.77	69.98	-0.042
3.77	69.98	-0.042
3.77	69.98	-0.042
3.77	69.98	-0.042
3.77	69.98	-0.042
3.78	69.98	-0.042
3.78	69.98	-0.042
3.78	69.98	-0.042
3.78	69.98	-0.042
3.78	69.98	-0.042
3.78	69.98	-0.042
3.79	69.98	-0.041
3.79	69.98	-0.041
3.79	69.98	-0.041
3.79	69.98	-0.041
3.79	69.98	-0.041
3.79	69.98	-0.041
3.79	69.98	-0.041
3.80	69.98	-0.041
3.80	69.98	-0.041
3.80	69.98	-0.041
3.80	69.98	-0.041
3.80	69.98	-0.041
3.81	69.98	-0.041
3.81	69.98	-0.041
3.81	69.98	-0.041
3.81	69.98	-0.041
3.81	69.98	-0.041
3.81	69.98	-0.041
3.81	69.98	-0.041
3.82	69.98	-0.041
3.82	69.98	-0.041
3.82	69.98	-0.041
3.82	69.98	-0.040
3.82	69.98	-0.040
3.83	69.98	-0.040
3.83	69.98	-0.040
3.83	69.98	-0.040
3.83	69.98	-0.040
3.83	69.98	-0.040
3.83	69.98	-0.040
3.84	69.98	-0.040
3.84	69.98	-0.040
3.84	69.98	-0.040
3.84	69.98	-0.040
3.84	69.98	-0.040
3.84	69.98	-0.040
3.84	69.98	-0.040
3.85	69.98	-0.040
3.85	69.98	-0.040
3.85	69.98	-0.039
3.85	69.98	-0.039
3.85	69.98	-0.039
3.86	69.98	-0.039
3.86	69.98	-0.039
3.86	69.98	-0.039
3.86	69.98	-0.039
3.86	69.98	-0.039
3.86	69.98	-0.039
3.86	69.98	-0.039
3.87	69.98	-0.039
3.87	69.98	-0.039
3.87	69.98	-0.039
3.87	69.98	-0.039
3.87	69.98	-0.039
3.88	69.99	-0.039
3.88	69.98	-0.039
3.88	69.99	-0.039
3.88	69.99	-0.039
3.88	69.98	-0.039
3.88	69.99	-0.039
3.89	69.99	-0.039
3.89	69.99	-0.039
3.89	69.99	-0.039
3.89	69.98	-0.038
3.89	69.99	-0.038
3.89	69.99	-0.038
3.89	69.99	-0.038
3.90	69.99	-0.038
3.90	69.99	-0.038
3.90	69.98	-0.038
3.90	69.99	-0.038
3.90	69.99	-0.038
3.91	69.99	-0.038
3.91	69.98	-0.038
3.91	69.99	-0.038
3.91	69.99	-0.038
3.91	69.99	-0.038
3.91	69.99	-0.038
3.91	69.99	-0.038
3.92	69.99	-0.038
3.92	69.99	-0.038
3.92	69.99	-0.038
3.92	69.99	-0.038
3.92	69.99	-0.038
3.93	69.99	-0.038
3.93	69.99	-0.038
3.93	69.99	-0.038
3.93	69.99	-0.038
3.93	69.99	-0.037
3.93	69.99	-0.037
3.94	69.99	-0.037
3.94	69.99	-0.037
3.94	69.99	-0.037
3.94	69.99	-0.037
3.94	69.99	-0.037
3.94	69.99	-0.037
3.94	69.99	-0.037
3.95	69.99	-0.037
3.95	69.99	-0.037
3.95	69.99	-0.037
3.95	69.99	-0.037
3.95	69.99	-0.037
3.96	69.99	-0.037
3.96	69.99	-0.037
3.96	69.99	-0.037
3.96	69.99	-0.037
3.96	69.99	-0.037
3.96	69.99	-0.037
3.96	69.99	-0.037
3.97	69.99	-0.037
3.97	69.99	-0.037
3.97	69.99	-0.037
3.97	69.99	-0.037
3.97	69.99	-0.036
3.98	69.99	-0.036
3.98	69.99	-0.036
3.98	69.99	-0.036
3.98	69.99	-0.036
3.98	69.99	-0.036
3.98	69.99	-0.036
3.99	69.99	-0.036
3.99	69.99	-0.036
3.99	69.99	-0.036
3.99	69.99	-0.036
3.99	69.99	-0.036
3.99	69.99	-0.036
3.99	69.99	-0.036
4.00	69.99	-0.036
4.00	69.99	-0.036
4.00	69.99	-0.036

[step]
Ramp 10.00 °C/min to 300.00 °C
Time	Temperature	Heat Flow (Normalized)
min	°C	W/g
4.00	69.99	-0.036
4.02	69.99	-0.035
4.04	69.99	-0.035
4.05	70.01	-0.057
4.07	70.03	-0.117
4.09	70.08	-0.220
4.10	70.14	-0.357
4.12	70.22	-0.505
4.14	70.32	-0.645
4.15	70.43	-0.764
4.17	70.55	-0.861
4.19	70.67	-0.943
4.20	70.81	-1.012
4.22	70.94	-1.073
4.24	71.09	-1.126
4.25	71.23	-1.171
4.27	71.38	-1.211
4.29	71.53	-1.244
4.30	71.69	-1.271
4.32	71.85	-1.294
4.34	72.00	-1.313
4.35	72.16	-1.328
4.37	72.32	-1.343
4.39	72.48	-1.355
4.40	72.65	-1.365
4.42	72.81	-1.374
4.44	72.97	-1.383
4.45	73.14	-1.388
4.47	73.30	-1.394
4.49	73.46	-1.399
4.50	73.63	-1.402
4.52	73.79	-1.405
4.54	73.96	-1.408
4.55	74.12	-1.412
4.57	74.29	-1.413
4.59	74.45	-1.416
4.60	74.62	-1.418
4.62	74.78	-1.419
4.64	74.95	-1.419
4.65	75.12	-1.420
4.67	75.28	-1.421
4.69	75.45	-1.421
4.70	75.61	-1.422
4.72	75.78	-1.423
4.74	75.95	-1.423
4.75	76.11	-1.424
4.77	76.28	-1.425
4.79	76.44	-1.425
4.80	76.61	-1.426
4.82	76.78	-1.427
4.84	76.94	-1.427
4.85	77.11	-1.428
4.87	77.27	-1.429
4.89	77.44	-1.429
4.90	77.61	-1.430
4.92	77.77	-1.430
4.94	77.94	-1.431
4.95	78.11	-1.432
4.97	78.27	-1.433
4.99	78.44	-1.433
5.00	78.61	-1.434
5.02	78.77	-1.434
5.04	78.94	-1.435
5.05	79.10	-1.435
5.07	79.27	-1.436
5.09	79.44	-1.436
5.10	79.60	-1.437
5.12	79.77	-1.437
5.14	79.94	-1.438
5.15	80.10	-1.438
5.17	80.27	-1.439
5.19	80.44	-1.439
5.20	80.60	-1.439
5.22	80.77	-1.440
5.24	80.94	-1.440
5.25	81.10	-1.441
5.27	81.27	-1.441
5.29	81.44	-1.442
5.30	81.60	-1.442
5.32	81.77	-1.443
5.34	81.94	-1.443
5.35	82.10	-1.444
5.37	82.27	-1.444
5.39	82.44	-1.444
5.40	82.60	-1.445
5.42	82.77	-1.445
5.44	82.94	-1.446
5.45	83.10	-1.446
5.47	83.27	-1.447
5.49	83.44	-1.447
5.50	83.60	-1.448
5.52	83.77	-1.448
5.54	83.94	-1.448
5.55	84.10	-1.449
5.57	84.27	-1.449
5.59	84.44	-1.450
5.60	84.60	-1.450
5.62	84.77	-1.450
5.64	84.94	-1.451
5.65	85.10	-1.451
5.67	85.27	-1.452
5.69	85.44	-1.452
5.70	85.60	-1.453
5.72	85.77	-1.453
5.74	85.94	-1.454
5.75	86.10	-1.454
5.77	86.27	-1.454
5.79	86.44	-1.455
5.80	86.60	-1.455
5.82	86.77	-1.456
5.84	86.94	-1.456
5.85	87.10	-1.457
5.87	87.27	-1.457
5.89	87.44	-1.458
5.90	87.60	-1.458
5.92	87.77	-1.459
5.94	87.93	-1.460
5.95	88.10	-1.460
5.97	88.27	-1.462
5.99	88.44	-1.463
6.00	88.60	-1.464
6.02	88.77	-1.464
6.04	88.93	-1.466
6.05	89.10	-1.467
6.07	89.27	-1.468
6.09	89.43	-1.470
6.10	89.60	-1.472
6.12	89.77	-1.473
6.14	89.93	-1.475
6.15	90.10	-1.477
6.17	90.27	-1.479
6.19	90.43	-1.480
6.20	90.60	-1.482
6.22	90.77	-1.485
6.24	90.93	-1.486
6.25	91.10	-1.488
6.27	91.26	-1.490
6.29	91.43	-1.492
6.30	91.60	-1.494
6.32	91.76	-1.495
6.34	91.93	-1.497
6.35	92.10	-1.498
6.37	92.26	-1.499
6.39	92.43	-1.499
6.40	92.60	-1.499
6.42	92.76	-1.499
6.44	92.93	-1.490
6.45	93.10	-1.489
6.47	93.27	-1.490
6.49	93.43	-1.490
6.50	93.60	-1.490
6.52	93.77	-1.490
6.54	93.93	-1.489
6.55	94.10	-1.491
6.57	94.27	-1.492
6.59	94.43	-1.492
6.60	94.60	-1.492
6.62	94.77	-1.493
6.64	94.93	-1.493
6.65	95.10	-1.493
6.67	95.27	-1.492
6.69	95.44	-1.489
6.70	95.60	-1.489
6.72	95.77	-1.489
6.74	95.93	-1.522
6.75	96.10	-1.516
6.77	96.27	-1.514
6.79	96.43	-1.513
6.80	96.60	-1.513
6.82	96.77	-1.513
6.84	96.93	-1.513
6.85	97.10	-1.513
6.87	97.26	-1.513
6.89	97.43	-1.513
6.90	97.60	-1.513
6.92	97.76	-1.513
6.94	97.93	-1.513
6.95	98.10	-1.513
6.97	98.27	-1.513
6.99	98.43	-1.513
7.00	98.60	-1.513
7.02	98.77	-1.513
7.04	98.93	-1.513
7.05	99.10	-1.513
7.07	99.27	-1.513
7.09	99.43	-1.513
7.10	99.60	-1.513
7.12	99.77	-1.513
7.14	99.93	-1.513
7.15	100.10	-1.513
7.17	100.27	-1.513
7.19	100.43	-1.513
7.20	100.60	-1.513
7.22	100.77	-1.513
7.24	100.93	-1.513
7.25	101.10	-1.513
7.27	101.27	-1.513
7.29	101.44	-1.514
7.30	101.60	-1.514
7.32	101.77	-1.514
7.34	101.94	-1.514
7.35	102.10	-1.514
7.37	102.27	-1.514
7.39	102.44	-1.514
7.40	102.60	-1.514
7.42	102.77	-1.515
7.44	102.94	-1.515
7.45	103.10	-1.515
7.47	103.27	-1.515
7.49	103.44	-1.515
7.50	103.60	-1.515
7.52	103.77	-1.516
7.54	103.94	-1.516
7.55	104.10	-1.516
7.57	104.27	-1.516
7.59	104.44	-1.516
7.60	104.60	-1.516
7.62	104.77	-1.517
7.64	104.94	-1.517
7.65	105.10	-1.517
7.67	105.27	-1.517
7.69	105.44	-1.517
7.70	105.60	-1.517
7.72	105.77	-1.518
7.74	105.94	-1.518
7.75	106.10	-1.518
7.77	106.27	-1.518
7.79	106.44	-1.518
7.80	106.61	-1.519
7.82	106.77	-1.519
7.84	106.94	-1.519
7.85	107.10	-1.519
7.87	107.27	-1.519
7.89	107.44	-1.519
7.90	107.61	-1.519
7.92	107.77	-1.520
7.94	107.94	-1.520
7.95	108.11	-1.520
7.97	108.27	-1.520
7.99	108.44	-1.520
8.00	108.61	-1.520
8.02	108.77	-1.521
8.04	108.94	-1.521
8.05	109.11	-1.521
8.07	109.27	-1.521
8.09	109.44	-1.521
8.10	109.61	-1.521
8.12	109.77	-1.521
8.14	109.94	-1.522
8.15	110.11	-1.522
8.17	110.27	-1.522
8.19	110.44	-1.522
8.20	110.61	-1.522
8.22	110.77	-1.522
8.24	110.94	-1.523
8.25	111.11	-1.523
8.27	111.27	-1.523
8.29	111.44	-1.523
8.30	111.61	-1.523
8.32	111.77	-1.523
8.34	111.94	-1.523
8.35	112.11	-1.523
8.37	112.28	-1.523
8.39	112.44	-1.523
8.40	112.61	-1.523
8.42	112.78	-1.523
8.44	112.94	-1.523
8.45	113.11	-1.523
8.47	113.28	-1.523
8.49	113.44	-1.523
8.50	113.61	-1.523
8.52	113.78	-1.523
8.53	113.94	-1.523
8.55	114.11	-1.523
8.57	114.28	-1.523
8.58	114.44	-1.523
8.60	114.61	-1.523
8.62	114.78	-1.523
8.63	114.94	-1.523
8.65	115.11	-1.522
8.67	115.28	-1.522
8.68	115.44	-1.522
8.70	115.61	-1.522
8.72	115.78	-1.521
8.73	115.95	-1.521
8.75	116.11	-1.521
8.77	116.28	-1.521
8.78	116.45	-1.520
8.80	116.61	-1.520
8.82	116.78	-1.520
8.83	116.95	-1.519
8.85	117.11	-1.519
8.87	117.28	-1.518
8.88	117.45	-1.518
8.90	117.62	-1.517
8.92	117.78	-1.517
8.93	117.95	-1.516
8.95	118.12	-1.515
8.97	118.28	-1.515
8.98	118.45	-1.514
9.00	118.62	-1.513
9.02	118.79	-1.513
9.03	118.95	-1.512
9.05	119.12	-1.511
9.07	119.29	-1.510
9.08	119.45	-1.509
9.10	119.62	-1.508
9.12	119.79	-1.507
9.13	119.95	-1.505
9.15	120.12	-1.504
9.17	120.29	-1.502
9.18	120.46	-1.501
9.20	120.62	-1.498
9.22	120.79	-1.497
9.23	120.96	-1.495
9.25	121.12	-1.493
9.27	121.29	-1.492
9.28	121.46	-1.489
9.30	121.63	-1.487
9.32	121.79	-1.484
9.33	121.96	-1.481
9.35	122.13	-1.477
9.37	122.30	-1.474
9.38	122.46	-1.469
9.40	122.63	-1.464
9.42	122.80	-1.459
9.43	122.97	-1.454
9.45	123.13	-1.450
9.47	123.30	-1.443
9.48	123.47	-1.436
9.50	123.64	-1.430
9.52	123.81	-1.423
9.53	123.97	-1.414
9.55	124.14	-1.403
9.57	124.31	-1.392
9.58	124.48	-1.382
9.60	124.65	-1.368
9.62	124.82	-1.354
9.63	124.99	-1.338
9.65	125.16	-1.320
9.67	125.33	-1.305
9.68	125.50	-1.284
9.70	125.67	-1.265
9.72	125.84	-1.241
9.73	126.02	-1.220
9.75	126.19	-1.195
9.77	126.36	-1.170
9.78	126.53	-1.145
9.80	126.70	-1.120
9.82	126.88	-1.094
9.83	127.05	-1.068
9.85	127.22	-1.043
9.87	127.40	-1.021
9.88	127.57	-0.999
9.90	127.74	-0.979
9.92	127.91	-0.961
9.93	128.08	-0.943
9.95	128.26	-0.928
9.97	128.43	-0.917
9.98	128.59	-0.909
10.00	128.77	-0.905
10.02	128.93	-0.902
10.03	129.10	-0.904
10.05	129.27	-0.912
10.07	129.43	-0.920
10.08	129.60	-0.939
10.10	129.76	-0.960
10.12	129.93	-0.983
10.13	130.09	-1.010
10.15	130.25	-1.039
10.17	130.41	-1.068
10.18	130.57	-1.102
10.20	130.73	-1.133
10.22	130.89	-1.165
10.23	131.05	-1.195
10.25	131.21	-1.225
10.27	131.37	-1.253
10.28	131.53	-1.281
10.30	131.69	-1.304
10.32	131.85	-1.328
10.33	132.01	-1.348
10.35	132.17	-1.368
10.37	132.34	-1.383
10.38	132.50	-1.399
10.40	132.66	-1.413
10.42	132.82	-1.424
10.43	132.99	-1.435
10.45	133.15	-1.445
10.47	133.31	-1.454
10.48	133.48	-1.463
10.50	133.64	-1.469
10.52	133.81	-1.477
10.53	133.97	-1.481
10.55	134.14	-1.486
10.57	134.30	-1.490
10.58	134.47	-1.494
10.60	134.63	-1.496
10.62	134.80	-1.500
10.63	134.97	-1.502
10.65	135.13	-1.505
10.67	135.30	-1.508
10.68	135.47	-1.510
10.70	135.63	-1.513
10.72	135.80	-1.514
10.73	135.96	-1.515
10.75	136.13	-1.516
10.77	136.30	-1.516
10.78	136.46	-1.518
10.80	136.63	-1.519
10.82	136.80	-1.520
10.83	136.96	-1.521
10.85	137.13	-1.522
10.87	137.29	-1.523
10.88	137.46	-1.524
10.90	137.63	-1.525
10.92	137.80	-1.525
10.93	137.96	-1.526
10.95	138.13	-1.527
10.97	138.30	-1.527
10.98	138.46	-1.528
11.00	138.63	-1.528
11.02	138.79	-1.529
11.03	138.96	-1.530
11.05	139.13	-1.530
11.07	139.29	-1.531
11.08	139.46	-1.532
11.10	139.63	-1.532
11.12	139.79	-1.533
11.13	139.96	-1.533
11.15	140.13	-1.534
11.17	140.29	-1.535
11.18	140.46	-1.536
11.20	140.63	-1.537
11.22	140.80	-1.537
11.23	140.96	-1.538
11.25	141.13	-1.539
11.27	141.29	-1.539
11.28	141.46	-1.540
11.30	141.63	-1.540
11.32	141.79	-1.541
11.33	141.96	-1.541
11.35	142.13	-1.542
11.37	142.29	-1.542
11.38	142.46	-1.543
11.40	142.63	-1.543
11.42	142.79	-1.544
11.43	142.96	-1.544
11.45	143.13	-1.545
11.47	143.29	-1.545
11.48	143.46	-1.546
11.50	143.63	-1.547
11.52	143.79	-1.547
11.53	143.96	-1.548
11.55	144.13	-1.548
11.57	144.29	-1.549
11.58	144.46	-1.549
11.60	144.63	-1.550
11.62	144.79	-1.550
11.63	144.96	-1.551
11.65	145.13	-1.551
11.67	145.29	-1.552
11.68	145.46	-1.552
[...]
33.40	237.44	1.899
33.42	237.26	1.931
33.44	237.08	1.969
33.46	236.91	2.003
33.48	236.73	2.043
33.49	236.56	2.082
33.51	236.38	2.125
33.53	236.21	2.168
33.55	236.03	2.209
33.57	235.86	2.249
33.58	235.68	2.290
33.60	235.51	2.328
33.62	235.33	2.366
33.64	235.16	2.400
33.66	234.98	2.430
33.68	234.80	2.456
33.69	234.63	2.475
33.71	234.45	2.492
33.73	234.27	2.500
33.75	234.09	2.502
33.77	233.90	2.498
33.79	233.72	2.485
33.81	233.54	2.468
33.82	233.35	2.440
33.84	233.16	2.409
33.86	232.98	2.371
33.88	232.78	2.327
33.90	232.59	2.280
33.92	232.40	2.230
33.93	232.21	2.178
33.95	232.01	2.125
33.97	231.82	2.071
33.99	231.63	2.015
34.01	231.43	1.965
34.03	231.24	1.915
34.04	231.04	1.870
34.06	230.85	1.825
34.08	230.66	1.785
34.10	230.47	1.746
34.12	230.28	1.715
34.14	230.09	1.685
34.15	229.90	1.659
34.17	229.71	1.636
34.19	229.52	1.616
34.21	229.33	1.599
34.23	229.15	1.583
34.24	228.96	1.570
34.26	228.77	1.559
34.28	228.59	1.547
34.30	228.40	1.538
34.32	228.22	1.531
34.34	228.03	1.524
34.36	227.85	1.517
34.37	227.66	1.512
34.39	227.48	1.507
34.41	227.29	1.503
34.43	227.11	1.498
34.45	226.92	1.495
34.46	226.74	1.491
34.48	226.56	1.489
34.50	226.37	1.486
34.52	226.19	1.484
34.54	226.00	1.482
34.56	225.82	1.480
34.58	225.64	1.478
34.59	225.45	1.476
34.61	225.27	1.474
34.63	225.09	1.473
34.65	224.90	1.471
34.67	224.72	1.470
34.69	224.54	1.469
34.70	224.35	1.468
34.72	224.17	1.467
34.74	223.99	1.466
34.76	223.80	1.465
34.78	223.62	1.464
34.79	223.43	1.463
34.81	223.25	1.462
34.83	223.07	1.461
34.85	222.88	1.460
34.87	222.70	1.459
34.89	222.52	1.458
34.91	222.33	1.458
34.92	222.15	1.457
34.94	221.97	1.456
34.96	221.78	1.456
34.98	221.60	1.455
35.00	221.42	1.454
35.01	221.23	1.453
35.03	221.05	1.453
35.05	220.87	1.452
35.07	220.68	1.451
35.09	220.50	1.450
35.11	220.32	1.450
35.13	220.13	1.449
35.14	219.95	1.449
35.16	219.77	1.448
35.18	219.58	1.447
35.20	219.40	1.447
35.22	219.22	1.446
35.24	219.03	1.445
35.25	218.85	1.445
35.27	218.67	1.444
35.29	218.48	1.444
35.31	218.30	1.443
35.33	218.12	1.443
35.34	217.93	1.442
35.36	217.75	1.442
35.38	217.57	1.441
35.40	217.38	1.441
35.42	217.20	1.440
35.44	217.02	1.440
35.46	216.83	1.439
35.47	216.65	1.439
35.49	216.47	1.439
35.51	216.28	1.438
35.53	216.10	1.438
35.55	215.92	1.437
35.56	215.74	1.437
35.58	215.55	1.436
35.60	215.37	1.436
35.62	215.19	1.436
35.64	215.00	1.435
35.66	214.82	1.435
35.68	214.64	1.435
35.69	214.45	1.434
35.71	214.27	1.434
35.73	214.09	1.434
35.75	213.90	1.433
35.77	213.72	1.433
35.79	213.54	1.433
35.80	213.35	1.432
35.82	213.17	1.432
35.84	212.99	1.432
35.86	212.80	1.431
35.88	212.62	1.431
35.89	212.44	1.431
35.91	212.25	1.430
35.93	212.07	1.430
35.95	211.89	1.430
35.97	211.70	1.430
35.99	211.52	1.429
36.01	211.34	1.429
36.02	211.16	1.429
36.04	210.97	1.429
36.06	210.79	1.428
36.08	210.60	1.428
36.10	210.42	1.428
36.11	210.24	1.428
36.13	210.05	1.427
36.15	209.87	1.427
36.17	209.69	1.427
36.19	209.51	1.427
36.21	209.32	1.427
36.23	209.14	1.426
36.24	208.96	1.426
36.26	208.77	1.426
36.28	208.59	1.426
36.30	208.41	1.425
36.32	208.22	1.425
36.34	208.04	1.425
36.35	207.86	1.425
36.37	207.67	1.425
36.39	207.49	1.425
36.41	207.31	1.424
36.43	207.12	1.424
36.44	206.94	1.424
36.46	206.76	1.424
36.48	206.57	1.424
36.50	206.39	1.424
36.52	206.21	1.424
36.54	206.02	1.424
36.56	205.84	1.424
36.57	205.66	1.423
36.59	205.47	1.423
36.61	205.29	1.423
36.63	205.11	1.423
36.65	204.92	1.423
36.66	204.74	1.423
36.68	204.56	1.423
36.70	204.37	1.423
36.72	204.19	1.422
36.74	204.01	1.422
36.76	203.83	1.422
36.78	203.64	1.422
36.79	203.46	1.422
36.81	203.28	1.422
36.83	203.09	1.422
36.85	202.91	1.422
36.87	202.73	1.422
36.89	202.54	1.421
36.90	202.36	1.421
36.92	202.18	1.421
36.94	201.99	1.421
36.96	201.81	1.421
36.98	201.63	1.421
36.99	201.44	1.420
37.01	201.26	1.420
37.03	201.08	1.420
37.05	200.89	1.420
37.07	200.71	1.420
37.09	200.53	1.420
37.11	200.34	1.420
37.12	200.16	1.420
37.14	199.98	1.419
37.16	199.79	1.419
37.18	199.61	1.419
37.20	199.43	1.419
37.21	199.25	1.419
37.23	199.06	1.419
37.25	198.88	1.419
37.27	198.70	1.419
37.29	198.51	1.418
37.31	198.33	1.418
37.33	198.15	1.418
37.34	197.96	1.418
37.36	197.78	1.418
37.38	197.60	1.418
37.40	197.41	1.418
37.42	197.23	1.418
37.44	197.05	1.418
37.45	196.86	1.418
37.47	196.68	1.418
37.49	196.50	1.417
37.51	196.31	1.417
37.53	196.13	1.417
37.54	195.95	1.417
37.56	195.76	1.417
37.58	195.58	1.417
37.60	195.40	1.417
37.62	195.21	1.417
37.64	195.03	1.417
37.66	194.85	1.416
37.67	194.66	1.416
37.69	194.48	1.416
37.71	194.30	1.416
37.73	194.12	1.416
37.75	193.93	1.416
37.76	193.75	1.416
37.78	193.57	1.416
37.80	193.38	1.416
37.82	193.20	1.416
37.84	193.02	1.416
37.86	192.83	1.416
37.88	192.65	1.416
37.89	192.47	1.416
37.91	192.28	1.416
37.93	192.10	1.416
37.95	191.92	1.415
37.97	191.73	1.415
37.99	191.55	1.415
38.00	191.37	1.415
38.02	191.18	1.415
38.04	191.00	1.415
38.06	190.82	1.415
38.08	190.64	1.415
38.09	190.45	1.415
38.11	190.27	1.415
38.13	190.09	1.415
38.15	189.90	1.415
38.17	189.72	1.415
38.19	189.54	1.415
38.21	189.35	1.415
38.22	189.17	1.414
38.24	188.99	1.414
38.26	188.80	1.414
38.28	188.62	1.414
38.30	188.44	1.414
38.31	188.25	1.414
38.33	188.07	1.414
38.35	187.89	1.414
38.37	187.70	1.414
38.39	187.52	1.414
38.41	187.34	1.414
38.43	187.15	1.414
38.44	186.97	1.414
38.46	186.79	1.414
38.48	186.60	1.414
38.50	186.42	1.414
38.52	186.24	1.414
38.54	186.05	1.414
38.55	185.87	1.414
38.57	185.69	1.414
38.59	185.51	1.414
38.61	185.32	1.414
38.63	185.14	1.414
38.64	184.96	1.414
38.66	184.77	1.414
38.68	184.59	1.414
38.70	184.41	1.414
38.72	184.22	1.414
38.74	184.04	1.414
38.76	183.86	1.414
38.77	183.67	1.413
38.79	183.49	1.413
38.81	183.31	1.413
38.83	183.12	1.413
38.85	182.94	1.413
38.86	182.76	1.413
38.88	182.57	1.413
38.90	182.39	1.413
38.92	182.21	1.413
38.94	182.03	1.413
38.96	181.84	1.413
38.98	181.66	1.413
38.99	181.48	1.413
39.01	181.29	1.413
39.03	181.11	1.412
39.05	180.93	1.412
39.07	180.74	1.412
39.09	180.56	1.412
39.10	180.38	1.412
39.12	180.19	1.412
39.14	180.01	1.412
39.16	179.83	1.412
39.18	179.64	1.412
39.19	179.46	1.412
39.21	179.28	1.412
39.23	179.09	1.412
39.25	178.91	1.412
39.27	178.73	1.412
39.29	178.54	1.412
39.31	178.36	1.412
39.32	178.18	1.412
39.34	177.99	1.412
39.36	177.81	1.412
39.38	177.63	1.412
39.40	177.44	1.412
39.41	177.26	1.411
39.43	177.08	1.411
39.45	176.90	1.411
39.47	176.71	1.411
39.49	176.53	1.411
39.51	176.35	1.411
39.53	176.16	1.411
39.54	175.98	1.411
39.56	175.80	1.411
39.58	175.61	1.411
39.60	175.43	1.411
39.62	175.25	1.411
39.64	175.06	1.411
39.65	174.88	1.411
39.67	174.70	1.411
39.69	174.51	1.411
39.71	174.33	1.411
39.73	174.15	1.411
39.74	173.97	1.411
39.76	173.78	1.411
39.78	173.60	1.411
39.80	173.42	1.411
39.82	173.23	1.411
39.84	173.05	1.411
39.86	172.86	1.411
39.87	172.68	1.411
39.89	172.50	1.410
39.91	172.32	1.410
39.93	172.13	1.410
39.95	171.95	1.410
39.96	171.77	1.410
39.98	171.58	1.410
40.00	171.40	1.410
40.02	171.22	1.410
40.04	171.03	1.410
40.06	170.85	1.410
40.08	170.67	1.410
40.09	170.48	1.410
40.11	170.30	1.410
40.13	170.12	1.409
40.15	169.93	1.409
40.17	169.75	1.409
40.19	169.57	1.409
40.20	169.38	1.409
40.22	169.20	1.409
40.24	169.02	1.409
40.26	168.84	1.409
40.28	168.65	1.409
40.29	168.47	1.409
40.31	168.29	1.409
40.33	168.10	1.409
40.35	167.92	1.408
40.37	167.74	1.408
40.39	167.55	1.408
40.41	167.37	1.408
40.42	167.19	1.408
40.44	167.00	1.408
40.46	166.82	1.408
40.48	166.64	1.408
40.50	166.45	1.408
40.51	166.27	1.408
40.53	166.09	1.408
40.55	165.90	1.408
40.57	165.72	1.408
40.59	165.54	1.408
40.61	165.35	1.408
40.63	165.17	1.408
40.64	164.99	1.408
40.66	164.80	1.408
40.68	164.62	1.408
40.70	164.44	1.408
40.72	164.26	1.408
40.74	164.07	1.408
40.75	163.89	1.408
40.77	163.71	1.408
40.79	163.52	1.408
40.81	163.34	1.408
40.83	163.16	1.408
40.84	162.97	1.408
40.86	162.79	1.408
40.88	162.61	1.408
40.90	162.42	1.408
40.92	162.24	1.408
40.94	162.06	1.408
40.96	161.88	1.408
40.97	161.69	1.408
40.99	161.51	1.408
41.01	161.33	1.408
41.03	161.14	1.408
41.05	160.96	1.408
41.06	160.78	1.408
41.08	160.59	1.407
41.10	160.41	1.407
41.12	160.23	1.407
41.14	160.04	1.407
41.16	159.86	1.407
41.18	159.68	1.407
41.19	159.49	1.407
41.21	159.31	1.407
41.23	159.13	1.407
41.25	158.94	1.407
41.27	158.76	1.407
41.29	158.58	1.407
41.30	158.39	1.407
41.32	158.21	1.407
41.34	158.03	1.407
41.36	157.84	1.406
41.38	157.66	1.406
41.39	157.48	1.406
41.41	157.29	1.406
41.43	157.11	1.406
41.45	156.93	1.406
41.47	156.74	1.406
41.49	156.56	1.406
41.51	156.38	1.406
41.52	156.20	1.406
41.54	156.01	1.406
41.56	155.83	1.406
41.58	155.65	1.406
41.60	155.46	1.406
41.61	155.28	1.405
41.63	155.10	1.405
41.65	154.91	1.405
41.67	154.73	1.405
41.69	154.55	1.405
41.71	154.36	1.405
41.73	154.18	1.405
41.74	154.00	1.405
41.76	153.81	1.405
41.78	153.63	1.405
41.80	153.45	1.405
41.82	153.26	1.405
41.84	153.08	1.405
41.85	152.90	1.405
41.87	152.72	1.405
41.89	152.53	1.405
41.91	152.35	1.405
41.93	152.17	1.405
41.94	151.98	1.405
41.96	151.80	1.405
41.98	151.62	1.404
42.00	151.43	1.404
42.02	151.25	1.404
42.04	151.07	1.404
42.06	150.88	1.404
42.07	150.70	1.404
42.09	150.52	1.404
42.11	150.33	1.404
42.13	150.15	1.404
42.15	149.97	1.404
42.16	149.78	1.404
42.18	149.60	1.404
42.20	149.42	1.404
42.22	149.23	1.404
42.24	149.05	1.404
42.26	148.87	1.404
42.28	148.69	1.403
42.29	148.50	1.403
42.31	148.32	1.403
42.33	148.13	1.403
42.35	147.95	1.403
42.37	147.77	1.403
42.39	147.59	1.403
42.40	147.40	1.403
42.42	147.22	1.403
42.44	147.04	1.403
42.46	146.85	1.403
42.48	146.67	1.403
42.49	146.49	1.403
42.51	146.30	1.403
42.53	146.12	1.403
42.55	145.94	1.402
42.57	145.75	1.402
42.59	145.57	1.402
42.61	145.39	1.402
42.62	145.20	1.402
42.64	145.02	1.402
42.66	144.84	1.402
42.68	144.66	1.402
42.70	144.47	1.402
42.71	144.29	1.402
42.73	144.11	1.402
42.75	143.92	1.402
42.77	143.74	1.402
42.79	143.56	1.402
42.81	143.37	1.402
42.83	143.19	1.402
42.84	143.01	1.401
42.86	142.82	1.401
42.88	142.64	1.401
42.90	142.46	1.401
42.92	142.27	1.401
42.94	142.09	1.401
42.95	141.91	1.401
42.97	141.72	1.401
42.99	141.54	1.401
43.01	141.36	1.401
43.03	141.17	1.401
43.04	140.99	1.401
43.06	140.81	1.401
43.08	140.63	1.401
43.10	140.44	1.400
43.12	140.26	1.400
43.14	140.08	1.400
43.16	139.89	1.400
43.17	139.71	1.400
43.19	139.53	1.400
43.21	139.34	1.400
43.23	139.16	1.400
43.25	138.98	1.400
43.26	138.79	1.400
43.28	138.61	1.400
43.30	138.43	1.400
43.32	138.24	1.400
43.34	138.06	1.400
43.36	137.88	1.400
43.38	137.70	1.399
43.39	137.51	1.399
43.41	137.33	1.399
43.43	137.15	1.399
43.45	136.96	1.399
43.47	136.78	1.399
43.49	136.60	1.399
43.50	136.41	1.399
43.52	136.23	1.399
43.54	136.05	1.399
43.56	135.86	1.399
43.58	135.68	1.399
43.59	135.50	1.399
43.61	135.31	1.399
43.63	135.13	1.399
43.65	134.95	1.399
43.67	134.76	1.399
43.69	134.58	1.399
43.71	134.40	1.398
43.72	134.22	1.398
43.74	134.03	1.398
43.76	133.85	1.398
43.78	133.67	1.398
43.80	133.48	1.398
43.81	133.30	1.398
43.83	133.12	1.398
43.85	132.93	1.398
43.87	132.75	1.398
43.89	132.57	1.398
43.91	132.38	1.398
43.93	132.20	1.398
43.94	132.02	1.398
43.96	131.83	1.398
43.98	131.65	1.398
44.00	131.47	1.398
44.02	131.28	1.398
44.04	131.10	1.398
44.05	130.92	1.398
44.07	130.74	1.398
44.09	130.55	1.398
44.11	130.37	1.398
44.13	130.18	1.398
44.14	130.00	1.398
44.16	129.82	1.398
44.18	129.64	1.398
44.20	129.45	1.397
44.22	129.27	1.397
44.24	129.09	1.397
44.26	128.90	1.397
44.27	128.72	1.397
44.29	128.54	1.397
44.31	128.35	1.397
44.33	128.17	1.397
44.35	127.99	1.397
44.36	127.80	1.397
44.38	127.62	1.397
44.40	127.44	1.397
44.42	127.25	1.396
44.44	127.07	1.396
44.46	126.89	1.396
44.48	126.70	1.396
44.49	126.52	1.396
44.51	126.34	1.396
44.53	126.15	1.396
44.55	125.97	1.396
44.57	125.79	1.396
44.59	125.61	1.396
44.60	125.42	1.396
44.62	125.24	1.396
44.64	125.06	1.396
44.66	124.87	1.396
44.68	124.69	1.395
44.69	124.51	1.395
44.71	124.32	1.395
44.73	124.14	1.395
44.75	123.96	1.395
44.77	123.77	1.395
44.79	123.59	1.395
44.81	123.41	1.395
44.82	123.22	1.395
44.84	123.04	1.395
44.86	122.86	1.395
44.88	122.67	1.395
44.90	122.49	1.395
44.91	122.31	1.395
44.93	122.12	1.395
44.95	121.94	1.395
44.97	121.76	1.394
44.99	121.58	1.394
45.01	121.39	1.394
45.03	121.21	1.394
45.04	121.03	1.394
45.06	120.84	1.394
45.08	120.66	1.394
45.10	120.48	1.394
45.12	120.29	1.394
45.14	120.11	1.394
45.15	119.93	1.393
45.17	119.74	1.394
45.19	119.56	1.393
45.21	119.38	1.393
45.23	119.19	1.393
45.24	119.01	1.393
45.26	118.83	1.393
45.28	118.65	1.393
45.30	118.46	1.393
45.32	118.28	1.393
45.34	118.10	1.393
45.36	117.91	1.393
45.37	117.73	1.393
45.39	117.55	1.393
45.41	117.36	1.392
45.43	117.18	1.392
45.45	117.00	1.392
45.46	116.81	1.392
45.48	116.63	1.392
45.50	116.45	1.392
45.52	116.26	1.392
45.54	116.08	1.392
45.56	115.90	1.392
45.58	115.71	1.392
45.59	115.53	1.392
45.61	115.35	1.391
45.63	115.16	1.391
45.65	114.98	1.391
45.67	114.80	1.391
45.69	114.62	1.391
45.70	114.43	1.391
45.72	114.25	1.391
45.74	114.06	1.391
45.76	113.88	1.391
45.78	113.70	1.390
45.79	113.52	1.390
45.81	113.33	1.390
45.83	113.15	1.390
45.85	112.97	1.390
45.87	112.78	1.390
45.89	112.60	1.389
45.91	112.42	1.389
45.92	112.23	1.389
45.94	112.05	1.389
45.96	111.87	1.389
45.98	111.68	1.389
46.00	111.50	1.389
46.01	111.32	1.389
46.03	111.13	1.389
46.05	110.95	1.388
46.07	110.77	1.388
46.09	110.58	1.388
46.11	110.40	1.388
46.13	110.22	1.388
46.14	110.03	1.388
46.16	109.85	1.388
46.18	109.67	1.388
46.20	109.49	1.387
46.22	109.30	1.387
46.24	109.12	1.387
46.25	108.94	1.387
46.27	108.75	1.387
46.29	108.57	1.387
46.31	108.39	1.386
46.33	108.20	1.386
46.34	108.02	1.386
46.36	107.84	1.386
46.38	107.65	1.386
46.40	107.47	1.386
46.42	107.29	1.386
46.44	107.10	1.386
46.46	106.92	1.386
46.47	106.74	1.385
46.49	106.55	1.385
46.51	106.37	1.385
46.53	106.19	1.385
46.55	106.00	1.385
46.56	105.82	1.385
46.58	105.64	1.384
46.60	105.46	1.384
46.62	105.27	1.384
46.64	105.09	1.384
46.66	104.91	1.384
46.68	104.72	1.383
46.69	104.54	1.383
46.71	104.36	1.383
46.73	104.17	1.383
46.75	103.99	1.383
46.77	103.81	1.383
46.79	103.62	1.383
46.80	103.44	1.383
46.82	103.26	1.383
46.84	103.07	1.383
46.86	102.89	1.382
46.88	102.71	1.382
46.89	102.53	1.382
46.91	102.34	1.382
46.93	102.16	1.382
46.95	101.98	1.382
46.97	101.79	1.382
46.99	101.61	1.381
47.01	101.43	1.381
47.02	101.24	1.381
47.04	101.06	1.381
47.06	100.88	1.381
47.08	100.69	1.381
47.10	100.51	1.381
47.11	100.33	1.380
47.13	100.14	1.380
47.15	99.96	1.380
47.17	99.78	1.380
47.19	99.59	1.380
47.21	99.41	1.380
47.23	99.23	1.379
47.24	99.04	1.379
47.26	98.86	1.379
47.28	98.68	1.379
47.30	98.49	1.379
47.32	98.31	1.379
47.34	98.13	1.378
47.35	97.95	1.378
47.37	97.76	1.378
47.39	97.58	1.378
47.41	97.40	1.378
47.43	97.21	1.377
47.44	97.03	1.377
47.46	96.85	1.377
47.48	96.66	1.377
47.50	96.48	1.376
47.52	96.30	1.376
47.54	96.11	1.376
47.56	95.93	1.376
47.57	95.75	1.376
47.59	95.56	1.376
47.61	95.38	1.375
47.63	95.20	1.375
47.65	95.01	1.375
47.66	94.83	1.375
47.68	94.65	1.374
47.70	94.46	1.374
47.72	94.28	1.374
47.74	94.10	1.374
47.76	93.92	1.374
47.78	93.73	1.373
47.79	93.55	1.373
47.81	93.37	1.373
47.83	93.18	1.373
47.85	93.00	1.373
47.87	92.82	1.372
47.89	92.63	1.372
47.90	92.45	1.372
47.92	92.27	1.372
47.94	92.08	1.372
47.96	91.90	1.371
47.98	91.72	1.371
47.99	91.53	1.371
48.01	91.35	1.371
48.03	91.17	1.371
48.05	90.98	1.370
48.07	90.80	1.370
48.09	90.62	1.370
48.11	90.43	1.370
48.12	90.25	1.370
48.14	90.07	1.369
48.16	89.89	1.369
48.18	89.70	1.369
48.20	89.52	1.369
48.21	89.34	1.369
48.23	89.15	1.368
48.25	88.97	1.368
48.27	88.78	1.368
48.29	88.60	1.368
48.31	88.42	1.367
48.33	88.24	1.367
48.34	88.05	1.367
48.36	87.87	1.367
48.38	87.69	1.366
48.40	87.50	1.366
48.42	87.32	1.366
48.44	87.14	1.365
48.45	86.95	1.361
48.47	86.77	1.362
48.49	86.59	1.362
48.51	86.40	1.362
48.53	86.22	1.362
48.54	86.04	1.362
48.56	85.85	1.362
48.58	85.67	1.362
48.60	85.49	1.362
48.62	85.30	1.362
48.64	85.12	1.362
48.66	84.94	1.362
48.67	84.76	1.362
48.69	84.57	1.362
48.71	84.39	1.362
48.73	84.21	1.362
48.75	84.02	1.361
48.76	83.84	1.361
48.78	83.66	1.361
48.80	83.47	1.361
48.82	83.29	1.361
48.84	83.11	1.361
48.86	82.92	1.361
48.88	82.74	1.361
48.89	82.56	1.361
48.91	82.37	1.361
48.93	82.19	1.361
48.95	82.01	1.361
48.97	81.82	1.360
48.99	81.64	1.360
49.00	81.46	1.360
49.02	81.28	1.360
49.04	81.09	1.360
49.06	80.91	1.360
49.08	80.73	1.360
49.09	80.54	1.360
49.11	80.36	1.360
49.13	80.18	1.359
49.15	79.99	1.359
49.17	79.81	1.359
49.19	79.63	1.359
49.21	79.44	1.359
49.22	79.26	1.359
49.24	79.08	1.359
49.26	78.89	1.359
49.28	78.71	1.359
49.30	78.53	1.358
49.31	78.35	1.358
49.33	78.16	1.358
49.35	77.98	1.358
49.37	77.79	1.358
49.39	77.61	1.358
49.41	77.43	1.358
49.43	77.25	1.357
49.44	77.06	1.357
49.46	76.88	1.357
49.48	76.70	1.357
49.50	76.51	1.357
49.52	76.33	1.357
49.54	76.15	1.357
49.55	75.96	1.357
49.57	75.78	1.356
49.59	75.60	1.356
49.61	75.41	1.356
49.63	75.23	1.356
49.64	75.05	1.356
49.66	74.86	1.356
49.68	74.68	1.356
49.70	74.50	1.355
49.72	74.31	1.355
49.74	74.13	1.355
49.76	73.95	1.355
49.77	73.77	1.355
49.79	73.58	1.355
49.81	73.40	1.355
49.83	73.22	1.354
49.85	73.03	1.354
49.86	72.85	1.354
49.88	72.67	1.354
49.90	72.48	1.354
49.92	72.30	1.354
49.94	72.12	1.354
49.96	71.93	1.354
49.98	71.75	1.353
49.99	71.57	1.353
50.01	71.39	1.353
50.03	71.20	1.353
50.05	71.02	1.353
50.07	70.83	1.353
50.09	70.65	1.353
50.10	70.47	1.353
50.12	70.29	1.353
50.14	70.10	1.352
50.16	69.92	1.352
50.18	69.74	1.352
50.19	69.55	1.352
50.21	69.37	1.352
50.23	69.19	1.352
50.25	69.00	1.352
50.27	68.82	1.352
50.29	68.64	1.352
50.31	68.45	1.352
50.32	68.27	1.352
50.34	68.09	1.351
50.36	67.90	1.351
50.38	67.72	1.351
50.40	67.54	1.351
50.41	67.36	1.351
50.43	67.17	1.351
50.45	66.99	1.351
50.47	66.81	1.351
50.49	66.62	1.350
50.51	66.44	1.350
50.53	66.26	1.350
50.54	66.07	1.350
50.56	65.89	1.350
50.58	65.71	1.350
50.60	65.52	1.349
50.62	65.34	1.349
50.64	65.16	1.349
50.65	64.98	1.349
50.67	64.79	1.349
50.69	64.61	1.348
50.71	64.43	1.348
50.73	64.24	1.348
50.74	64.06	1.348
50.76	63.88	1.348
50.78	63.69	1.348
50.80	63.51	1.348
50.82	63.33	1.347
50.84	63.14	1.347
50.86	62.96	1.347
50.87	62.78	1.347
50.89	62.59	1.347
50.91	62.41	1.347
50.93	62.23	1.347
50.95	62.04	1.347
50.96	61.86	1.347
50.98	61.68	1.347
51.00	61.50	1.346
51.02	61.31	1.346
51.04	61.13	1.346
51.06	60.95	1.346
51.08	60.76	1.346
51.09	60.58	1.346
51.11	60.40	1.346
51.13	60.21	1.346
51.15	60.03	1.346
51.17	59.85	1.345
51.19	59.66	1.345
51.20	59.48	1.345
51.22	59.30	1.345
51.24	59.12	1.345
51.26	58.93	1.345
51.28	58.75	1.345
51.29	58.57	1.345
51.31	58.38	1.345
51.33	58.20	1.344
51.35	58.02	1.344
51.37	57.83	1.344
51.39	57.65	1.344
51.41	57.47	1.344
51.42	57.28	1.344
51.44	57.10	1.344
51.46	56.92	1.344
51.48	56.73	1.343
51.50	56.55	1.343
51.51	56.37	1.343
51.53	56.19	1.343
51.55	56.00	1.343
51.57	55.82	1.343
51.59	55.64	1.343
51.61	55.45	1.343
51.63	55.27	1.343
51.64	55.09	1.342
51.66	54.90	1.342
51.68	54.72	1.342
51.70	54.54	1.342
51.72	54.35	1.342
51.74	54.17	1.342
51.75	53.99	1.342
51.77	53.80	1.342
51.79	53.62	1.341
51.81	53.44	1.341
51.83	53.25	1.341
51.84	53.07	1.341
51.86	52.89	1.341
51.88	52.71	1.341
51.90	52.52	1.341
51.92	52.34	1.341
51.94	52.16	1.340
51.96	51.97	1.340
51.97	51.79	1.340
51.99	51.61	1.340
52.01	51.42	1.340
52.03	51.24	1.340
52.05	51.06	1.339
52.06	50.87	1.339
52.08	50.69	1.339
52.10	50.51	1.339
52.12	50.32	1.339
52.14	50.14	1.339
52.16	49.96	1.338
52.18	49.77	1.338
52.19	49.59	1.338
52.21	49.41	1.338
52.23	49.23	1.338
52.25	49.04	1.337
52.27	48.86	1.337
52.29	48.68	1.337
52.30	48.49	1.337
52.32	48.31	1.337
52.34	48.13	1.337
52.36	47.94	1.337
52.38	47.76	1.337
52.39	47.58	1.336
52.41	47.39	1.336
52.43	47.21	1.336
52.45	47.03	1.336
52.47	46.84	1.336
52.49	46.66	1.336
52.51	46.48	1.335
52.52	46.30	1.335
52.54	46.11	1.335
52.56	45.93	1.335
52.58	45.75	1.335
52.60	45.56	1.335
52.61	45.38	1.334
52.63	45.20	1.334
52.65	45.01	1.334
52.67	44.83	1.334
52.69	44.65	1.334
52.71	44.46	1.333
52.73	44.28	1.333
52.74	44.10	1.333
52.76	43.91	1.333
52.78	43.73	1.333
52.80	43.55	1.333
52.82	43.37	1.332
52.84	43.18	1.332
52.85	43.00	1.332
52.87	42.82	1.332
52.89	42.63	1.332
52.91	42.45	1.331
52.93	42.27	1.331
52.94	42.08
52.96	41.90
52.98	41.72
53.00
53.00